Workbook
Name D_ACT: S4_Calc_Daily!$R$5:$R$11
Name D_ANOMALY: S4_Calc_Daily!$AE$5:$AE$11
Name D_AVGDUR: S4_Calc_Daily!$AJ$5:$AJ$11
Name D_AWAKE: S4_Calc_Daily!$M$5:$M$11
Name D_BEDMIN: S4_Calc_Daily!$C$5:$C$11
Name D_BUCKET: S4_Calc_Daily!$AA$5:$AA$11
Name D_DEEP_PCT: S4_Calc_Daily!$I$5:$I$11
Name D_HR: S4_Calc_Daily!$N$5:$N$11
Name D_KCAL_DEVICE: S4_Calc_Daily!$T$5:$T$11
Name D_LABEL: S4_Calc_Daily!$A$5:$A$11
Name D_LIGHT_PCT: S4_Calc_Daily!$J$5:$J$11
Name D_MONITORED: S4_Calc_Daily!$AL$5:$AL$11
Name D_MULTI: S4_Calc_Daily!$AH$5:$AH$11
Name D_REM_PCT: S4_Calc_Daily!$K$5:$K$11
Name D_RR: S4_Calc_Daily!$O$5:$O$11
Name D_SE: S4_Calc_Daily!$AQ$5:$AQ$11
Name D_SE_CALC: S4_Calc_Daily!$H$5:$H$11
Name D_SE_COMPARE_QA: S4_Calc_Daily!$AP$5:$AP$11
Name D_SE_DEVICE: S4_Calc_Daily!$AN$5:$AN$11
Name D_SE_DIFF: S4_Calc_Daily!$AO$5:$AO$11
Name D_SOL: S4_Calc_Daily!$L$5:$L$11
Name D_SPO2: S4_Calc_Daily!$P$5:$P$11
Name D_TDEE: S4_Calc_Daily!$X$5:$X$11
Name D_TIB: S4_Calc_Daily!$E$5:$E$11
Name D_TIB_QA: S4_Calc_Daily!$AM$5:$AM$11
Name D_TST: S4_Calc_Daily!$F$5:$F$11
Name D_TYPE: S4_Calc_Daily!$Z$5:$Z$11
Name D_VITAL: S4_Calc_Daily!$U$5:$U$11
Name D_WAKEMIN: S4_Calc_Daily!$D$5:$D$11
Name D_WASO_DEVICE: S4_Calc_Daily!$AI$5:$AI$11
Name D_WASO_QA: S4_Calc_Daily!$AK$5:$AK$11
Name IN_ACT: S1_Input_Raw!$N$5:$N$11
Name IN_AWAKE: S1_Input_Raw!$I$5:$I$11
Name IN_BEDTIME: S1_Input_Raw!$C$5:$C$11
Name IN_DATE: S1_Input_Raw!$B$5:$B$11
Name IN_DEEP: S1_Input_Raw!$F$5:$F$11
Name IN_HR: S1_Input_Raw!$J$5:$J$11
Name IN_KCAL_DEVICE: S1_Input_Raw!$P$5:$P$11
Name IN_LIGHT: S1_Input_Raw!$G$5:$G$11
Name IN_REM: S1_Input_Raw!$H$5:$H$11
Name IN_RR: S1_Input_Raw!$K$5:$K$11
Name IN_SE_DEVICE: S1_Input_Raw!$S$5:$S$11
Name IN_SOL: S1_Input_Raw!$E$5:$E$11
Name IN_SPO2: S1_Input_Raw!$L$5:$L$11
Name IN_SPO2MIN: S1_Input_Raw!$M$5:$M$11
Name IN_STEPS: S1_Input_Raw!$O$5:$O$11
Name IN_VITAL: S1_Input_Raw!$Q$5:$Q$11
Name IN_WAKETIME: S1_Input_Raw!$D$5:$D$11
Name IN_WASO_DEVICE: S1_Input_Raw!$R$5:$R$11
Name NR_ACT_AVG: S5_Calc_Weekly!$B$13
Name NR_ACT_DAILY_TARGET: S3_Config!$D$15
Name NR_ACT_MAX: S5_Calc_Weekly!$D$13
Name NR_ACT_MAXDAY: S5_Calc_Weekly!$G$13
Name NR_ACT_MIN: S5_Calc_Weekly!$C$13
Name NR_ACT_MINDAY: S5_Calc_Weekly!$H$13
Name NR_ACT_RANGE: S5_Calc_Weekly!$E$13
Name NR_ACT_SD: S5_Calc_Weekly!$F$13
Name NR_ACT_WEEKLY_REF: S3_Config!$B$14
Name NR_AGE: S2_Input_Profile!$B$7
Name NR_ANOM_COUNT: S5_Calc_Weekly!$B$69

Sheet S0_README
A1: 불면 중심 수면 리듬 진단 리포트 — 자동 계산 로직
A2: 웨어러블 원본 데이터를 입력하면 18페이지 리포트에 들어가는 모든 수치·판정·문구 초안이 자동 계산됩니다.
A4: 항목 | B4: 설명
A5: 이 파일의 목적 | B5: S1(원본 데이터)·S2(개인 프로필)만 실제 값으로 바꿔 넣으면, 나머지 시트가 리포트에 필요한 모든 숫자·참고범위 판정·상관관계·페이지별 문구 초안을 자동으로 다시 계산합니다.
A6: 시트 순서 | B6: S1_원본데이터입력 → S2_개인프로필입력 → S3_참고범위설정 → S4_일별계산 → S5_주간요약_상관관계 → S6_페이지별_문구초안 → S7_리포트값_요약
A7: 사용자가 입력하는 시트 (파란 글씨 = 입력 칸) | B7: S1_원본데이터입력 (요일별 원본값), S2_개인프로필입력 (체중/키/나이/성별)
A8: 사용자가 조정 가능한 시트 (노란 배경 = 조정 가능한 가정치) | B8: S3_참고범위설정 — 임상 참고범위는 의학적으로 정해진 값이지만, 목표치·이상신호 편차기준·MET 가정 등은 상황에 맞게 바꿀 수 있도록 노란색으로 표시했습니다.
A9: 자동 계산 시트 (검정 글씨 = 수식, 직접 수정하지 마세요) | B9: S4~S7은 전부 수식입니다. S1·S2·S3 값을 바꾸면 자동으로 갱신됩니다.
A10: 예시 데이터 | B10: 지금 S1·S2에는 실제 발행된 9/8~9/14 리포트(Version 61)의 샘플 수치가 미리 채워져 있습니다. 새 사람의 데이터를 넣을 때는 이 값을 지우고 실제 값으로 덮어쓰면 됩니다.
A11: 완전히 재현되지 않는 항목 | B11: 리포트 원문 중 일부 문장(16p 활동 3단계 평균 SE 71/80/84%, 18p '활동 58분 이상→SE 84%')은 원문 작성 시 반올림·서술적 요약이 섞여 있어, 이 파일의 실제 그룹 평균 수식 결과와 소수점 단위로 다를 수 있습니다. S6·S7에는 실제 수식 계산값이 표시되며, 이는 원문보다 더 정확한 값입니다.
A12: BMR/칼로리 추정 관련 주의 | B12: 샤오미 등 웨어러블 제조사는 정확한 칼로리 산출 알고리즘을 공개하지 않습니다. 이 파일의 BMR·추정 소모칼로리는 표준 공식(Mifflin-St Jeor)과 활동시간×MET 가정치로 만든 '참고용 추정치'이며, 기기 표시값과 정확히 일치하지 않을 수 있습니다.
A13: 이상신호 스크리닝 기준 | B13: '심박·호흡·SpO2가 같은 날 동시에 평소 대비 벗어났는지'를 판정하는 편차기준(S3 13~15행)은 원문 리포트에 정확한 수치가 공개되어 있지 않아, 이 파일에서 합리적 기본값(HR +8bpm / RR +2회 / SpO2 -2%p)으로 가정했습니다. 필요시 조정하세요.
A14: 각성시간_실측 (S1 마지막 열, 선택 입력) | B14: 웨어러블이 '각성횟수'와 별도로 알려주는 밤사이 총 깨어있던 시간(분)입니다. 입력하면 06페이지에 '평균 1회 각성 지속시간' 분석 카드(각성횟수와 지속시간이 서로 다른 정보를 담고 있는지 확인)가 자동 계산됩니다. 비워두면 TIB−입면잠복기−총수면시간의 잔차값으로 대체 추정하며, S5 '⑨ 각성 지속시간 QA' 행에서 실측값과 잔차값의 평균 차이를 확인할 수 있습니다.
A15: 취침시각·기상시각 → 침상시간(TIB) 자동계산 (15차 확정) | B15: 취침시각과 기상시각(둘 다 절대 시각, 앱에 표시된 값 그대로)만 입력하면 침상시간(TIB)은 S4에서 자동으로 계산됩니다 — 직접 계산해서 넣을 필요가 없습니다. 자정을 넘나드는 취침시각(예: 23:15)도 그대로 입력하면 됩니다. 14차 때 잠시 'TIB를 분 단위로 직접 입력'하는 방식으로 바꿨었으나, 실제로는 사용자가 매일 TIB를 손으로 계산해 넣어야 해서 더 번거롭고 오입력 위험도 커 15차에서 원래의 자동계산 방식으로 되돌렸습니다. 대신 취침시각·입면잠복기(SOL) 칸에 있던 서식 버그(날짜/시각 서식이 잘못 적용되어 값이 이상하게 보이던 문제, 14차에서 발견)는 그대로 고쳐진 상태로 유지됩니다.
... A19: 수면효율_최종_% — 기기값 우선 채택 (19차 신규) | B19: 리포트(04·07·16·17페이지 등)에 실제로 반영되는 수면효율은 이제 S4 'AQ 수면효율_최종_%' 열입니다: 웨어러블이 날짜별로 제공한 값이 있으면 그 값을 그대로 쓰고, 없는 날만 취침·기상시각 기준 계산값('H 수면효율_계산_%')으로 대신합니다. 방법: named range 'D_SE'가 기존 H열 대신 이 AQ열을 가리키도록 재지정했을 뿐이라, D_SE/NR_SE_*를 참조하는 S5의 주간 통계·상관계수·회귀식과 S6/S7의 07·16·17페이지 문구가 전부 수정 없이 자동으로 최종값을 쓰게 됩니다(named range 기반 설계의 이점). 계산값 단독 참조가 필요하면 새로 분리한 'D_SE_CALC' 이름을 쓰세요. 채택 이유: (1) 18차에서 샤오미의 계산식이 저희와 동일함을 확인했으므로 계산식 신뢰도 문제는 없음, (2) 웨어러블은 침상시간을 가속도계로 직접 감지해 사용자가 취침·기상시각을 손으로 입력하며 발생해온 오류(14~16차에서 반복적으로 고친 TIB 오입력·수면효율 100% 초과)의 원천 자체를 없앨 수 있음, (3) 100명 배치 처리 시 입력 항목이 하나 줄어 효율적. 04페이지 안내 문구에도 이 원칙을 반영.

Sheet S1_Input_Raw
A1: S1. 원본 데이터 입력
A2: 파란 글씨 칸에 웨어러블(예: 샤오미 미밴드) 앱에서 확인한 하루 단위 값을 입력하세요. 지금은 발행된 리포트(9/8~9/14)의 예시 값이 들어 있습니다.
A4: 요일 | B4: 날짜 | C4: 취침시각 | D4: 기상시각 | E4: 입면잠복기_분(SOL) | F4: 깊은수면_분 | G4: 얕은수면_분 | H4: 렘수면_분 | I4: 각성횟수_회 | J4: 심박수_평균_bpm | K4: 호흡수_평균_회/분 | L4: SpO2_평균_% | M4: SpO2_최저_%(선택) | N4: 활동시간_분 | O4: 걸음수_보(선택) | P4: 소모칼로리_기기값_kcal(선택) | Q4: 활력점수_기기값(0~100) | R4: 각성시간_실측_분(기기값,선택) | S4: 수면효율_기기값_%(선택,17차)
A5: 월 | B5: 46273 | C5: 0.027777778 | D5: 0.27430556 | E5: 19 | F5: 52 | G5: 159 | H5: 78 | I5: 2 | J5: 58 | K5: 15 | L5: 97 | M5: 96 | N5: 42 | O5: 6384 | P5: 1650 | Q5: 68 | R5: 44 | S5: 78
A6: 화 | B6: 46274 | C6: 0.0069444444 | D6: 0.27083333 | E6: 28 | F6: 40 | G6: 174 | H6: 75 | I6: 3 | J6: 61 | K6: 16 | L6: 96 | M6: 95 | N6: 31 | O6: 4712 | P6: 1580 | Q6: 64 | R6: 66 | S6: 74
A7: 수 | B7: 46275 | C7: 0.013888889 | D7: 0.26041667 | E7: 17 | F7: 59 | G7: 153 | H7: 83 | I7: 2 | J7: 57 | K7: 15 | L7: 97 | M7: 96 | N7: 55 | O7: 8360 | P7: 1720 | Q7: 72 | R7: 40 | S7: 84
A8: 목 | B8: 46276 | C8: 0.024305556 | D8: 0.28125 | E8: 32 | F8: 36 | G8: 167 | H8: 71 | I8: 3 | J8: 60 | K8: 16 | L8: 96 | M8: 95 | N8: 24 | O8: 3648 | P8: 1540 | Q8: 60 | R8: 69 | S8: 65
A9: 금 | B9: 46277 | C9: 0.045138889 | D9: 0.26388889 | E9: 34 | F9: 19 | G9: 141 | H9: 54 | I9: 4 | J9: 71 | K9: 19 | L9: 93 | M9: 92 | N9: 18 | O9: 2736 | P9: 1490 | Q9: 50 | R9: 63 | S9: 66
A10: 토 | B10: 46278 | C10: 0.96875 | D10: 0.29513889 | E10: 15 | F10: 88 | G10: 192 | H10: 120 | I10: 2 | J10: 55 | K10: 14 | L10: 98 | M10: 97 | N10: 62 | O10: 9424 | P10: 1780 | Q10: 74 | R10: 58 | S10: 83
A11: 일 | B11: 46279 | C11: 0.99652778 | D11: 0.28819444 | E11: 20 | F11: 65 | G11: 182 | H11: 97 | I11: 3 | J11: 56 | K11: 15 | L11: 97 | M11: 96 | N11: 45 | O11: 6840 | P11: 1660 | Q11: 70 | R11: 59 | S11: 79
A12: ※ 위 값은 2026.09.08~09.14 발행 리포트(Version 61)의 예시 데이터입니다. 새 대상자의 데이터로 교체해 사용하세요. SpO2_최저·걸음수·소모칼로리(기기값)·각성시간_실측은 선택 입력이며, 비워두면 관련 수식은 자동으로 빈 값을 반환합니다. 각성시간_실측은 기기가 '각성횟수'와 별도로 알려주는 밤사이 총 깨어있던 시간(분)입니다 — 입력하면 06페이지에 '평균 1회 각성 지속시간' 분석 카드가 추가로 계산됩니다. 비워두면 TIB−입면잠복기−총수면시간의 잔차값으로 대체 추정합니다. 취침시각·기상시각을 넣으면 침상시간(TIB)은 S4에서 자동으로 계산됩니다(직접 계산해서 넣지 않아도 됩니다) — 자정을 넘는 취침시각(예: 23:15)도 그대로 입력하면 됩니다. 입면잠복기(SOL)는 시각이 아니라 분 단위 숫자만 입력하세요. 수면효율_기기값은 웨어러블 앱이 날짜별로 따로 제공하는 수면효율(%)이 있으면 입력하세요 — 입력하면 S4에서 저희가 계산한 수면효율과 자동으로 비교해 차이가 큰 날을 표시합니다(비워두면 비교하지 않음).

Sheet S2_Input_Profile
A1: S2. 개인 프로필 입력
A2: 14페이지 소모칼로리(BMR 추정)에 사용됩니다. 파란 글씨 칸만 입력하세요.
A4: 항목 | B4: 값
A5: 이름(선택) | B5: 예시 대상자
A6: 성별 (남/여) | B6: 여
A7: 나이 (세) | B7: 45
A8: 체중 (kg) | B8: 58
A9: 키 (cm) | B9: 162
A11: BMI (자동계산) | B11: =IFERROR(B8/((B9/100)^2),"") -> 22.10029
A12: 기초대사량 BMR (자동계산, kcal/일) | B12: =IFERROR(IF(B6="남",10*B8+6.25*B9-5*B7+5,10*B8+6.25*B9-5*B7-161),"") -> 1206.5 | C12: Mifflin-St Jeor 공식 (1990). 남: 10W+6.25H-5A+5 / 여: 10W+6.25H-5A-161

Sheet S3_Config
A1: S3. 참고범위 및 가정치 설정
A2: 노란 칸은 조정 가능한 값입니다. 임상 참고범위(수면효율·입면잠복기 등)는 원 리포트에 쓰인 값을 기본값으로 넣었고, 목표치·이상신호 편차기준·MET 가정은 상황에 맞게 바꿀 수 있습니다.
A4: 항목 | B4: 하한 | C4: 상한 | D4: 목표/기준값 | E4: 단위 | F4: 비고 (출처/가정 근거)
A5: 총수면시간 (TST) | B5: 360 | C5: 480 | D5: 420 | E5: 분 | F5: 권장 6~8시간. 목표 7시간/일(주 49시간) — 3페이지 제안 카드 기준
A6: 수면효율 (SE) | B6: 85 | D6: 85 | E6: % | F6: 임상 참고범위 85% 이상 — 4페이지
A7: 입면잠복기 (SOL) | C7: 20 | D7: 20 | E7: 분 | F7: 임상 참고범위 20분 이내 — 5페이지
A8: 각성횟수 | C8: 2 | D8: 2 | E8: 회 | F8: 임상 참고범위 2회 이하 — 6페이지
A9: 심박수 (HR, 수면중) | B9: 45 | C9: 70 | E9: bpm | F9: 임상 참고범위 45~70bpm — 8페이지
A10: 호흡수 (RR, 수면중) | B10: 12 | C10: 20 | E10: 회/분 | F10: 임상 참고범위 12~20회/분 — 9페이지
A11: SpO2 | B11: 95 | E11: % | F11: 임상 참고범위 95% 이상 — 10페이지
A12: 취침시각 규칙성 (표준편차) | C12: 20 | E12: 분 | F12: 참고범위 20분 이내 — 11페이지
A13: 기상시각 규칙성 (표준편차) | C13: 20 | E13: 분 | F13: 참고범위 20분 이내 — 11페이지
A14: 활동시간 (주간 합계 권장) | B14: 150 | E14: 분/주 | F14: ACSM 등 국제 권고, 암 치료 후 회복기 중강도 유산소 — 13페이지
A15: 활동시간 목표 (일일, 루틴제안용) | D15: 50 | E15: 분/일 | F15: 18페이지 제안 카드 목표치 — 조정 가능
A16: 이상신호 편차기준 - 심박수 | B16: 8 | E16: bpm | F16: 주간 평소(평균) 대비 이 값 이상 높으면 이상 후보로 판정 — 원문 비공개, 합리적 기본값 가정
A17: 이상신호 편차기준 - 호흡수 | B17: 2 | E17: 회/분 | F17: 주간 평소 대비 이 값 이상 높으면 이상 후보 — 가정값
A18: 이상신호 편차기준 - SpO2 | B18: 2 | E18: %p | F18: 주간 평소 대비 이 값 이상 낮으면 이상 후보 — 가정값
A19: 활동 대사당량 가정 (MET) | B19: 4 | E19: MET | F19: 중강도 활동 가정. 실제 활동 강도에 따라 조정 — 14페이지 추정 칼로리 계산용
A20: 목표 수면시간 | D20: 7 | E20: 시간 | F20: 11페이지 목표 취침시각 역산용
A21: 목표 수면효율 | D21: 85 | E21: % | F21: 11페이지 목표 취침시각 역산용
A22: 기상시각 허용 변동폭 | D22: 30 | E22: 분 | F22: 18페이지 체크리스트 1번 기준
A23: 수면효율 계산-기기값 차이 허용기준 | D23: 5 | E23: %p | F23: 저희가 계산한 수면효율(TST/TIB×100)과 웨어러블이 날짜별로 따로 제공하는 수면효율의 차이가 이 값 이상이면 S4 'SE_비교_QA'에서 '차이 큼'으로 표시(17차) — 샤오미가 공개한 공식도 (실제수면시간÷침대에있던시간)×100으로 저희 계산식과 완전히 동일함을 확인(18차)했으므로, 계산식 자체 때문에 차이가 나는 것은 아니고 '침대에 있던 시간(TIB)'을 구하는 방식이 다른 것(사용자 직접 입력 vs 기기 가속도계 자동 감지)이 유일한 원인 후보임

Sheet S4_Calc_Daily
A1: S4. 일별 계산 (전부 수식)
A2: S1·S2·S3 값이 바뀌면 이 시트가 전부 자동으로 다시 계산됩니다. 직접 값을 입력하지 마세요.
A4: 요일 | B4: 날짜 | C4: 취침시각_분환산 | D4: 기상시각_분 | E4: 침상시간_TIB_분 | F4: 총수면시간_TST_분 | G4: 각성후재입면_WASO_분 | H4: 수면효율_계산_%(TST/TIB, 참고용) | I4: 깊은수면_비율_% | J4: 얕은수면_비율_% | K4: 렘수면_비율_% | L4: 입면잠복기_SOL_분 | M4: 각성횟수 | N4: 심박수_HR | O4: 호흡수_RR | P4: SpO2_평균 | Q4: SpO2_최저 | R4: 활동시간_분 | S4: 걸음수 | T4: 소모칼로리_기기값 | U4: 활력점수_기기값 | V4: BMR_kcal | W4: 활동소모칼로리_추정 | X4: TDEE_추정_kcal | Y4: 기기값-추정치_차이_kcal | Z4: 수면유형_분류 | AA4: 활동_버킷 | AB4: HR_평소대비편차 | AC4: RR_평소대비편차 | AD4: SpO2_평소대비편차(+면낮아짐) | AE4: 이상신호_해당여부 | AF4: 이날_활동최저여부 | AG4: 이날_활력최저여부 | AH4: 이상신호_다중영역여부 | AI4: 각성시간_실측또는추정_분 | AJ4: 평균각성지속시간_분(1회당) | AK4: 실측-잔차값_차이_분 | AL4: 모니터링_여부 | AM4: TIB_정합성_QA | AN4: 수면효율_기기값_% | AO4: 계산-기기값_SE차이_%p | AP4: SE_비교_QA | AQ4: 수면효율_최종_%(리포트 반영값, 19차)
A5: =S1_Input_Raw!A5 -> 월 | B5: =S1_Input_Raw!B5 -> 46273 | C5: =IF(OR(ISBLANK(S1_Input_Raw!C5),ISBLANK(S1_Input_Raw!D5),ISBLANK(S1_Input_Raw!F5)),"",IF(S1_Input_Raw!C5>=0.5,(S1_Input_Raw!C5-1)*1440,S1_Input_Raw!C5*1440)) -> 40 | D5: =IF(OR(ISBLANK(S1_Input_Raw!C5),ISBLANK(S1_Input_Raw!D5),ISBLANK(S1_Input_Raw!F5)),"",S1_Input_Raw!D5*1440) -> 395 | E5: =IF(OR(ISBLANK(S1_Input_Raw!C5),ISBLANK(S1_Input_Raw!D5),ISBLANK(S1_Input_Raw!F5)),"",D5-C5) -> 355 | F5: =IF(OR(ISBLANK(S1_Input_Raw!C5),ISBLANK(S1_Input_Raw!D5),ISBLANK(S1_Input_Raw!F5)),"",S1_Input_Raw!F5+S1_Input_Raw!G5+S1_Input_Raw!H5) -> 289 | G5: =IF(OR(ISBLANK(S1_Input_Raw!C5),ISBLANK(S1_Input_Raw!D5),ISBLANK(S1_Input_Raw!F5)),"",E5-S1_Input_Raw!E5-F5) -> 47 | H5: =IF(OR(ISBLANK(S1_Input_Raw!C5),ISBLANK(S1_Input_Raw!D5),ISBLANK(S1_Input_Raw!F5)),"",IFERROR(F5/E5*100,"")) -> 81.408451 | I5: =IF(OR(ISBLANK(S1_Input_Raw!C5),ISBLANK(S1_Input_Raw!D5),ISBLANK(S1_Input_Raw!F5)),"",IFERROR(S1_Input_Raw!F5/F5*100,"")) -> 17.99308 | J5: =IF(OR(ISBLANK(S1_Input_Raw!C5),ISBLANK(S1_Input_Raw!D5),ISBLANK(S1_Input_Raw!F5)),"",IFERROR(S1_Input_Raw!G5/F5*100,"")) -> 55.017301 | K5: =IF(OR(ISBLANK(S1_Input_Raw!C5),ISBLANK(S1_Input_Raw!D5),ISBLANK(S1_Input_Raw!F5)),"",IFERROR(S1_Input_Raw!H5/F5*100,"")) -> 26.989619 | L5: =IF(OR(ISBLANK(S1_Input_Raw!C5),ISBLANK(S1_Input_Raw!D5),ISBLANK(S1_Input_Raw!F5)),"",S1_Input_Raw!E5) -> 19 | M5: =IF(OR(ISBLANK(S1_Input_Raw!C5),ISBLANK(S1_Input_Raw!D5),ISBLANK(S1_Input_Raw!F5)),"",S1_Input_Raw!I5) -> 2 | N5: =IF(OR(ISBLANK(S1_Input_Raw!C5),ISBLANK(S1_Input_Raw!D5),ISBLANK(S1_Input_Raw!F5)),"",S1_Input_Raw!J5) -> 58 | O5: =IF(OR(ISBLANK(S1_Input_Raw!C5),ISBLANK(S1_Input_Raw!D5),ISBLANK(S1_Input_Raw!F5)),"",S1_Input_Raw!K5) -> 15 | P5: =IF(OR(ISBLANK(S1_Input_Raw!C5),ISBLANK(S1_Input_Raw!D5),ISBLANK(S1_Input_Raw!F5)),"",S1_Input_Raw!L5) -> 97 | Q5: =IF(OR(ISBLANK(S1_Input_Raw!C5),ISBLANK(S1_Input_Raw!D5),ISBLANK(S1_Input_Raw!F5)),"",S1_Input_Raw!M5) -> 96 | R5: =IF(OR(ISBLANK(S1_Input_Raw!C5),ISBLANK(S1_Input_Raw!D5),ISBLANK(S1_Input_Raw!F5)),"",S1_Input_Raw!N5) -> 42 | S5: =IF(OR(ISBLANK(S1_Input_Raw!C5),ISBLANK(S1_Input_Raw!D5),ISBLANK(S1_Input_Raw!F5)),"",S1_Input_Raw!O5) -> 6384 | T5: =IF(OR(ISBLANK(S1_Input_Raw!C5),ISBLANK(S1_Input_Raw!D5),ISBLANK(S1_Input_Raw!F5)),"",S1_Input_Raw!P5) -> 1650 | U5: =IF(OR(ISBLANK(S1_Input_Raw!C5),ISBLANK(S1_Input_Raw!D5),ISBLANK(S1_Input_Raw!F5)),"",S1_Input_Raw!Q5) -> 68 | V5: =IF(OR(ISBLANK(S1_Input_Raw!C5),ISBLANK(S1_Input_Raw!D5),ISBLANK(S1_Input_Raw!F5)),"",NR_BMR) -> 1206.5 | W5: =IF(OR(ISBLANK(S1_Input_Raw!C5),ISBLANK(S1_Input_Raw!D5),ISBLANK(S1_Input_Raw!F5)),"",IFERROR(NR_MET*3.5*NR_WEIGHT/200*R5,"")) -> 170.52 | X5: =IF(OR(ISBLANK(S1_Input_Raw!C5),ISBLANK(S1_Input_Raw!D5),ISBLANK(S1_Input_Raw!F5)),"",IFERROR(V5+W5,"")) -> 1377.02 | Y5: =IF(OR(ISBLANK(S1_Input_Raw!C5),ISBLANK(S1_Input_Raw!D5),ISBLANK(S1_Input_Raw!F5)),"",IFERROR(T5-X5,"")) -> 272.98 | Z5: =IF(OR(ISBLANK(S1_Input_Raw!C5),ISBLANK(S1_Input_Raw!D5),ISBLANK(S1_Input_Raw!F5)),"",IF(AND(L5>NR_SOL_REF,M5>NR_AWAKE_REF,AQ5<NR_SE_REF),"복합형(잠들기어려움+자주깨어남)",IF(AND(L5<=NR_SOL_REF,M5>NR_AWAKE_REF),"자주깨어남형",IF(AND(L5>NR_SOL_REF,M5<=NR_AWAKE_REF),"잠들기어려움형","양호")))) -> 양호 | AA5: =IF(OR(ISBLANK(S1_Input_Raw!C5),ISBLANK(S1_Input_Raw!D5),ISBLANK(S1_Input_Raw!F5)),"",IFERROR(IF(R5<=PERCENTILE($R$5:$R$11,1/3),"저활동",IF(R5<=PERCENTILE($R$5:$R$11,2/3),"중활동","고활동")),"")) -> 중활동 | AB5: =IF(OR(ISBLANK(S1_Input_Raw!C5),ISBLANK(S1_Input_Raw!D5),ISBLANK(S1_Input_Raw!F5)),"",N5-AVERAGE($N$5:$N$11)) -> -1.7142857 | AC5: =IF(OR(ISBLANK(S1_Input_Raw!C5),ISBLANK(S1_Input_Raw!D5),ISBLANK(S1_Input_Raw!F5)),"",O5-AVERAGE($O$5:$O$11)) -> -0.71428571 | AD5: =IF(OR(ISBLANK(S1_Input_Raw!C5),ISBLANK(S1_Input_Raw!D5),ISBLANK(S1_Input_Raw!F5)),"",AVERAGE($P$5:$P$11)-P5) -> -0.71428571 | AE5: =IF(OR(ISBLANK(S1_Input_Raw!C5),ISBLANK(S1_Input_Raw!D5),ISBLANK(S1_Input_Raw!F5)),FALSE(),AND(AB5>=NR_DEV_HR,AC5>=NR_DEV_RR,AD5>=NR_DEV_SPO2)) -> FALSE | AF5: =IF(OR(ISBLANK(S1_Input_Raw!C5),ISBLANK(S1_Input_Raw!D5),ISBLANK(S1_Input_Raw!F5)),FALSE(),R5=MIN($R$5:$R$11)) -> FALSE | AG5: =IF(OR(ISBLANK(S1_Input_Raw!C5),ISBLANK(S1_Input_Raw!D5),ISBLANK(S1_Input_Raw!F5)),FALSE(),U5=MIN($U$5:$U$11)) -> FALSE | AH5: =IF(OR(ISBLANK(S1_Input_Raw!C5),ISBLANK(S1_Input_Raw!D5),ISBLANK(S1_Input_Raw!F5)),FALSE(),AND(AE5,OR(AF5,AG5))) -> FALSE | AI5: =IF(OR(ISBLANK(S1_Input_Raw!C5),ISBLANK(S1_Input_Raw!D5),ISBLANK(S1_Input_Raw!F5)),"",IF(S1_Input_Raw!R5="",G5,S1_Input_Raw!R5)) -> 44 | AJ5: =IF(OR(ISBLANK(S1_Input_Raw!C5),ISBLANK(S1_Input_Raw!D5),ISBLANK(S1_Input_Raw!F5)),"",IFERROR(AI5/M5,"")) -> 22 | AK5: =IF(OR(ISBLANK(S1_Input_Raw!C5),ISBLANK(S1_Input_Raw!D5),ISBLANK(S1_Input_Raw!F5)),"",IF(S1_Input_Raw!R5="",0,AI5-G5)) -> -3 | AL5: =IF(OR(ISBLANK(S1_Input_Raw!C5),ISBLANK(S1_Input_Raw!D5),ISBLANK(S1_Input_Raw!F5)),"미모니터링","모니터링됨") -> 모니터링됨 | AM5: =IF(OR(ISBLANK(S1_Input_Raw!C5),ISBLANK(S1_Input_Raw!D5),ISBLANK(S1_Input_Raw!F5)),"",IF(G5<0,"⚠ TIB가 SOL+TST보다 작음 — 취침·기상시각 확인 필요","정상")) -> 정상 | AN5: =IF(OR(ISBLANK(S1_Input_Raw!C5),ISBLANK(S1_Input_Raw!D5),ISBLANK(S1_Input_Raw!F5)),"",IF(S1_Input_Raw!S5="","",S1_Input_Raw!S5)) -> 78 | AO5: =IF(OR(ISBLANK(S1_Input_Raw!C5),ISBLANK(S1_Input_Raw!D5),ISBLANK(S1_Input_Raw!F5)),"",IF(AN5="","",H5-AN5)) -> 3.4084507 | AP5: =IF(OR(ISBLANK(S1_Input_Raw!C5),ISBLANK(S1_Input_Raw!D5),ISBLANK(S1_Input_Raw!F5)),"",IF(AN5="","",IF(ABS(AO5)>=NR_SE_DIFF_REF,"⚠ 차이 큼 — 취침·기상시각 자동감지 방식 차이일 수 있음","일치"))) -> 일치 | AQ5: =IF(OR(ISBLANK(S1_Input_Raw!C5),ISBLANK(S1_Input_Raw!D5),ISBLANK(S1_Input_Raw!F5)),"",IF(AN5="",H5,AN5)) -> 78
A6: =S1_Input_Raw!A6 -> 화 | B6: =S1_Input_Raw!B6 -> 46274 | C6: =IF(OR(ISBLANK(S1_Input_Raw!C6),ISBLANK(S1_Input_Raw!D6),ISBLANK(S1_Input_Raw!F6)),"",IF(S1_Input_Raw!C6>=0.5,(S1_Input_Raw!C6-1)*1440,S1_Input_Raw!C6*1440)) -> 10 | D6: =IF(OR(ISBLANK(S1_Input_Raw!C6),ISBLANK(S1_Input_Raw!D6),ISBLANK(S1_Input_Raw!F6)),"",S1_Input_Raw!D6*1440) -> 390 | E6: =IF(OR(ISBLANK(S1_Input_Raw!C6),ISBLANK(S1_Input_Raw!D6),ISBLANK(S1_Input_Raw!F6)),"",D6-C6) -> 380 | F6: =IF(OR(ISBLANK(S1_Input_Raw!C6),ISBLANK(S1_Input_Raw!D6),ISBLANK(S1_Input_Raw!F6)),"",S1_Input_Raw!F6+S1_Input_Raw!G6+S1_Input_Raw!H6) -> 289 | G6: =IF(OR(ISBLANK(S1_Input_Raw!C6),ISBLANK(S1_Input_Raw!D6),ISBLANK(S1_Input_Raw!F6)),"",E6-S1_Input_Raw!E6-F6) -> 63 | H6: =IF(OR(ISBLANK(S1_Input_Raw!C6),ISBLANK(S1_Input_Raw!D6),ISBLANK(S1_Input_Raw!F6)),"",IFERROR(F6/E6*100,"")) -> 76.052632 | I6: =IF(OR(ISBLANK(S1_Input_Raw!C6),ISBLANK(S1_Input_Raw!D6),ISBLANK(S1_Input_Raw!F6)),"",IFERROR(S1_Input_Raw!F6/F6*100,"")) -> 13.84083 | J6: =IF(OR(ISBLANK(S1_Input_Raw!C6),ISBLANK(S1_Input_Raw!D6),ISBLANK(S1_Input_Raw!F6)),"",IFERROR(S1_Input_Raw!G6/F6*100,"")) -> 60.207612 | K6: =IF(OR(ISBLANK(S1_Input_Raw!C6),ISBLANK(S1_Input_Raw!D6),ISBLANK(S1_Input_Raw!F6)),"",IFERROR(S1_Input_Raw!H6/F6*100,"")) -> 25.951557 | L6: =IF(OR(ISBLANK(S1_Input_Raw!C6),ISBLANK(S1_Input_Raw!D6),ISBLANK(S1_Input_Raw!F6)),"",S1_Input_Raw!E6) -> 28 | M6: =IF(OR(ISBLANK(S1_Input_Raw!C6),ISBLANK(S1_Input_Raw!D6),ISBLANK(S1_Input_Raw!F6)),"",S1_Input_Raw!I6) -> 3 | N6: =IF(OR(ISBLANK(S1_Input_Raw!C6),ISBLANK(S1_Input_Raw!D6),ISBLANK(S1_Input_Raw!F6)),"",S1_Input_Raw!J6) -> 61 | O6: =IF(OR(ISBLANK(S1_Input_Raw!C6),ISBLANK(S1_Input_Raw!D6),ISBLANK(S1_Input_Raw!F6)),"",S1_Input_Raw!K6) -> 16 | P6: =IF(OR(ISBLANK(S1_Input_Raw!C6),ISBLANK(S1_Input_Raw!D6),ISBLANK(S1_Input_Raw!F6)),"",S1_Input_Raw!L6) -> 96 | Q6: =IF(OR(ISBLANK(S1_Input_Raw!C6),ISBLANK(S1_Input_Raw!D6),ISBLANK(S1_Input_Raw!F6)),"",S1_Input_Raw!M6) -> 95 | R6: =IF(OR(ISBLANK(S1_Input_Raw!C6),ISBLANK(S1_Input_Raw!D6),ISBLANK(S1_Input_Raw!F6)),"",S1_Input_Raw!N6) -> 31 | S6: =IF(OR(ISBLANK(S1_Input_Raw!C6),ISBLANK(S1_Input_Raw!D6),ISBLANK(S1_Input_Raw!F6)),"",S1_Input_Raw!O6) -> 4712 | T6: =IF(OR(ISBLANK(S1_Input_Raw!C6),ISBLANK(S1_Input_Raw!D6),ISBLANK(S1_Input_Raw!F6)),"",S1_Input_Raw!P6) -> 1580 | U6: =IF(OR(ISBLANK(S1_Input_Raw!C6),ISBLANK(S1_Input_Raw!D6),ISBLANK(S1_Input_Raw!F6)),"",S1_Input_Raw!Q6) -> 64 | V6: =IF(OR(ISBLANK(S1_Input_Raw!C6),ISBLANK(S1_Input_Raw!D6),ISBLANK(S1_Input_Raw!F6)),"",NR_BMR) -> 1206.5 | W6: =IF(OR(ISBLANK(S1_Input_Raw!C6),ISBLANK(S1_Input_Raw!D6),ISBLANK(S1_Input_Raw!F6)),"",IFERROR(NR_MET*3.5*NR_WEIGHT/200*R6,"")) -> 125.86 | X6: =IF(OR(ISBLANK(S1_Input_Raw!C6),ISBLANK(S1_Input_Raw!D6),ISBLANK(S1_Input_Raw!F6)),"",IFERROR(V6+W6,"")) -> 1332.36 | Y6: =IF(OR(ISBLANK(S1_Input_Raw!C6),ISBLANK(S1_Input_Raw!D6),ISBLANK(S1_Input_Raw!F6)),"",IFERROR(T6-X6,"")) -> 247.64 | Z6: =IF(OR(ISBLANK(S1_Input_Raw!C6),ISBLANK(S1_Input_Raw!D6),ISBLANK(S1_Input_Raw!F6)),"",IF(AND(L6>NR_SOL_REF,M6>NR_AWAKE_REF,AQ6<NR_SE_REF),"복합형(잠들기어려움+자주깨어남)",IF(AND(L6<=NR_SOL_REF,M6>NR_AWAKE_REF),"자주깨어남형",IF(AND(L6>NR_SOL_REF,M6<=NR_AWAKE_REF),"잠들기어려움형","양호")))) -> 복합형(잠들기어려움+자주깨어남) | AA6: =IF(OR(ISBLANK(S1_Input_Raw!C6),ISBLANK(S1_Input_Raw!D6),ISBLANK(S1_Input_Raw!F6)),"",IFERROR(IF(R6<=PERCENTILE($R$5:$R$11,1/3),"저활동",IF(R6<=PERCENTILE($R$5:$R$11,2/3),"중활동","고활동")),"")) -> 저활동 | AB6: =IF(OR(ISBLANK(S1_Input_Raw!C6),ISBLANK(S1_Input_Raw!D6),ISBLANK(S1_Input_Raw!F6)),"",N6-AVERAGE($N$5:$N$11)) -> 1.2857143 | AC6: =IF(OR(ISBLANK(S1_Input_Raw!C6),ISBLANK(S1_Input_Raw!D6),ISBLANK(S1_Input_Raw!F6)),"",O6-AVERAGE($O$5:$O$11)) -> 0.28571429 | AD6: =IF(OR(ISBLANK(S1_Input_Raw!C6),ISBLANK(S1_Input_Raw!D6),ISBLANK(S1_Input_Raw!F6)),"",AVERAGE($P$5:$P$11)-P6) -> 0.28571429 | AE6: =IF(OR(ISBLANK(S1_Input_Raw!C6),ISBLANK(S1_Input_Raw!D6),ISBLANK(S1_Input_Raw!F6)),FALSE(),AND(AB6>=NR_DEV_HR,AC6>=NR_DEV_RR,AD6>=NR_DEV_SPO2)) -> FALSE | AF6: =IF(OR(ISBLANK(S1_Input_Raw!C6),ISBLANK(S1_Input_Raw!D6),ISBLANK(S1_Input_Raw!F6)),FALSE(),R6=MIN($R$5:$R$11)) -> FALSE | AG6: =IF(OR(ISBLANK(S1_Input_Raw!C6),ISBLANK(S1_Input_Raw!D6),ISBLANK(S1_Input_Raw!F6)),FALSE(),U6=MIN($U$5:$U$11)) -> FALSE | AH6: =IF(OR(ISBLANK(S1_Input_Raw!C6),ISBLANK(S1_Input_Raw!D6),ISBLANK(S1_Input_Raw!F6)),FALSE(),AND(AE6,OR(AF6,AG6))) -> FALSE | AI6: =IF(OR(ISBLANK(S1_Input_Raw!C6),ISBLANK(S1_Input_Raw!D6),ISBLANK(S1_Input_Raw!F6)),"",IF(S1_Input_Raw!R6="",G6,S1_Input_Raw!R6)) -> 66 | AJ6: =IF(OR(ISBLANK(S1_Input_Raw!C6),ISBLANK(S1_Input_Raw!D6),ISBLANK(S1_Input_Raw!F6)),"",IFERROR(AI6/M6,"")) -> 22 | AK6: =IF(OR(ISBLANK(S1_Input_Raw!C6),ISBLANK(S1_Input_Raw!D6),ISBLANK(S1_Input_Raw!F6)),"",IF(S1_Input_Raw!R6="",0,AI6-G6)) -> 3 | AL6: =IF(OR(ISBLANK(S1_Input_Raw!C6),ISBLANK(S1_Input_Raw!D6),ISBLANK(S1_Input_Raw!F6)),"미모니터링","모니터링됨") -> 모니터링됨 | AM6: =IF(OR(ISBLANK(S1_Input_Raw!C6),ISBLANK(S1_Input_Raw!D6),ISBLANK(S1_Input_Raw!F6)),"",IF(G6<0,"⚠ TIB가 SOL+TST보다 작음 — 취침·기상시각 확인 필요","정상")) -> 정상 | AN6: =IF(OR(ISBLANK(S1_Input_Raw!C6),ISBLANK(S1_Input_Raw!D6),ISBLANK(S1_Input_Raw!F6)),"",IF(S1_Input_Raw!S6="","",S1_Input_Raw!S6)) -> 74 | AO6: =IF(OR(ISBLANK(S1_Input_Raw!C6),ISBLANK(S1_Input_Raw!D6),ISBLANK(S1_Input_Raw!F6)),"",IF(AN6="","",H6-AN6)) -> 2.0526316 | AP6: =IF(OR(ISBLANK(S1_Input_Raw!C6),ISBLANK(S1_Input_Raw!D6),ISBLANK(S1_Input_Raw!F6)),"",IF(AN6="","",IF(ABS(AO6)>=NR_SE_DIFF_REF,"⚠ 차이 큼 — 취침·기상시각 자동감지 방식 차이일 수 있음","일치"))) -> 일치 | AQ6: =IF(OR(ISBLANK(S1_Input_Raw!C6),ISBLANK(S1_Input_Raw!D6),ISBLANK(S1_Input_Raw!F6)),"",IF(AN6="",H6,AN6)) -> 74
A7: =S1_Input_Raw!A7 -> 수 | B7: =S1_Input_Raw!B7 -> 46275 | C7: =IF(OR(ISBLANK(S1_Input_Raw!C7),ISBLANK(S1_Input_Raw!D7),ISBLANK(S1_Input_Raw!F7)),"",IF(S1_Input_Raw!C7>=0.5,(S1_Input_Raw!C7-1)*1440,S1_Input_Raw!C7*1440)) -> 20 | D7: =IF(OR(ISBLANK(S1_Input_Raw!C7),ISBLANK(S1_Input_Raw!D7),ISBLANK(S1_Input_Raw!F7)),"",S1_Input_Raw!D7*1440) -> 375 | E7: =IF(OR(ISBLANK(S1_Input_Raw!C7),ISBLANK(S1_Input_Raw!D7),ISBLANK(S1_Input_Raw!F7)),"",D7-C7) -> 355 | F7: =IF(OR(ISBLANK(S1_Input_Raw!C7),ISBLANK(S1_Input_Raw!D7),ISBLANK(S1_Input_Raw!F7)),"",S1_Input_Raw!F7+S1_Input_Raw!G7+S1_Input_Raw!H7) -> 295 | G7: =IF(OR(ISBLANK(S1_Input_Raw!C7),ISBLANK(S1_Input_Raw!D7),ISBLANK(S1_Input_Raw!F7)),"",E7-S1_Input_Raw!E7-F7) -> 43 | H7: =IF(OR(ISBLANK(S1_Input_Raw!C7),ISBLANK(S1_Input_Raw!D7),ISBLANK(S1_Input_Raw!F7)),"",IFERROR(F7/E7*100,"")) -> 83.098592 | I7: =IF(OR(ISBLANK(S1_Input_Raw!C7),ISBLANK(S1_Input_Raw!D7),ISBLANK(S1_Input_Raw!F7)),"",IFERROR(S1_Input_Raw!F7/F7*100,"")) -> 20 | J7: =IF(OR(ISBLANK(S1_Input_Raw!C7),ISBLANK(S1_Input_Raw!D7),ISBLANK(S1_Input_Raw!F7)),"",IFERROR(S1_Input_Raw!G7/F7*100,"")) -> 51.864407 | K7: =IF(OR(ISBLANK(S1_Input_Raw!C7),ISBLANK(S1_Input_Raw!D7),ISBLANK(S1_Input_Raw!F7)),"",IFERROR(S1_Input_Raw!H7/F7*100,"")) -> 28.135593 | L7: =IF(OR(ISBLANK(S1_Input_Raw!C7),ISBLANK(S1_Input_Raw!D7),ISBLANK(S1_Input_Raw!F7)),"",S1_Input_Raw!E7) -> 17 | M7: =IF(OR(ISBLANK(S1_Input_Raw!C7),ISBLANK(S1_Input_Raw!D7),ISBLANK(S1_Input_Raw!F7)),"",S1_Input_Raw!I7) -> 2 | N7: =IF(OR(ISBLANK(S1_Input_Raw!C7),ISBLANK(S1_Input_Raw!D7),ISBLANK(S1_Input_Raw!F7)),"",S1_Input_Raw!J7) -> 57 | O7: =IF(OR(ISBLANK(S1_Input_Raw!C7),ISBLANK(S1_Input_Raw!D7),ISBLANK(S1_Input_Raw!F7)),"",S1_Input_Raw!K7) -> 15 | P7: =IF(OR(ISBLANK(S1_Input_Raw!C7),ISBLANK(S1_Input_Raw!D7),ISBLANK(S1_Input_Raw!F7)),"",S1_Input_Raw!L7) -> 97 | Q7: =IF(OR(ISBLANK(S1_Input_Raw!C7),ISBLANK(S1_Input_Raw!D7),ISBLANK(S1_Input_Raw!F7)),"",S1_Input_Raw!M7) -> 96 | R7: =IF(OR(ISBLANK(S1_Input_Raw!C7),ISBLANK(S1_Input_Raw!D7),ISBLANK(S1_Input_Raw!F7)),"",S1_Input_Raw!N7) -> 55 | S7: =IF(OR(ISBLANK(S1_Input_Raw!C7),ISBLANK(S1_Input_Raw!D7),ISBLANK(S1_Input_Raw!F7)),"",S1_Input_Raw!O7) -> 8360 | T7: =IF(OR(ISBLANK(S1_Input_Raw!C7),ISBLANK(S1_Input_Raw!D7),ISBLANK(S1_Input_Raw!F7)),"",S1_Input_Raw!P7) -> 1720 | U7: =IF(OR(ISBLANK(S1_Input_Raw!C7),ISBLANK(S1_Input_Raw!D7),ISBLANK(S1_Input_Raw!F7)),"",S1_Input_Raw!Q7) -> 72 | V7: =IF(OR(ISBLANK(S1_Input_Raw!C7),ISBLANK(S1_Input_Raw!D7),ISBLANK(S1_Input_Raw!F7)),"",NR_BMR) -> 1206.5 | W7: =IF(OR(ISBLANK(S1_Input_Raw!C7),ISBLANK(S1_Input_Raw!D7),ISBLANK(S1_Input_Raw!F7)),"",IFERROR(NR_MET*3.5*NR_WEIGHT/200*R7,"")) -> 223.3 | X7: =IF(OR(ISBLANK(S1_Input_Raw!C7),ISBLANK(S1_Input_Raw!D7),ISBLANK(S1_Input_Raw!F7)),"",IFERROR(V7+W7,"")) -> 1429.8 | Y7: =IF(OR(ISBLANK(S1_Input_Raw!C7),ISBLANK(S1_Input_Raw!D7),ISBLANK(S1_Input_Raw!F7)),"",IFERROR(T7-X7,"")) -> 290.2 | Z7: =IF(OR(ISBLANK(S1_Input_Raw!C7),ISBLANK(S1_Input_Raw!D7),ISBLANK(S1_Input_Raw!F7)),"",IF(AND(L7>NR_SOL_REF,M7>NR_AWAKE_REF,AQ7<NR_SE_REF),"복합형(잠들기어려움+자주깨어남)",IF(AND(L7<=NR_SOL_REF,M7>NR_AWAKE_REF),"자주깨어남형",IF(AND(L7>NR_SOL_REF,M7<=NR_AWAKE_REF),"잠들기어려움형","양호")))) -> 양호 | AA7: =IF(OR(ISBLANK(S1_Input_Raw!C7),ISBLANK(S1_Input_Raw!D7),ISBLANK(S1_Input_Raw!F7)),"",IFERROR(IF(R7<=PERCENTILE($R$5:$R$11,1/3),"저활동",IF(R7<=PERCENTILE($R$5:$R$11,2/3),"중활동","고활동")),"")) -> 고활동 | AB7: =IF(OR(ISBLANK(S1_Input_Raw!C7),ISBLANK(S1_Input_Raw!D7),ISBLANK(S1_Input_Raw!F7)),"",N7-AVERAGE($N$5:$N$11)) -> -2.7142857 | AC7: =IF(OR(ISBLANK(S1_Input_Raw!C7),ISBLANK(S1_Input_Raw!D7),ISBLANK(S1_Input_Raw!F7)),"",O7-AVERAGE($O$5:$O$11)) -> -0.71428571 | AD7: =IF(OR(ISBLANK(S1_Input_Raw!C7),ISBLANK(S1_Input_Raw!D7),ISBLANK(S1_Input_Raw!F7)),"",AVERAGE($P$5:$P$11)-P7) -> -0.71428571 | AE7: =IF(OR(ISBLANK(S1_Input_Raw!C7),ISBLANK(S1_Input_Raw!D7),ISBLANK(S1_Input_Raw!F7)),FALSE(),AND(AB7>=NR_DEV_HR,AC7>=NR_DEV_RR,AD7>=NR_DEV_SPO2)) -> FALSE | AF7: =IF(OR(ISBLANK(S1_Input_Raw!C7),ISBLANK(S1_Input_Raw!D7),ISBLANK(S1_Input_Raw!F7)),FALSE(),R7=MIN($R$5:$R$11)) -> FALSE | AG7: =IF(OR(ISBLANK(S1_Input_Raw!C7),ISBLANK(S1_Input_Raw!D7),ISBLANK(S1_Input_Raw!F7)),FALSE(),U7=MIN($U$5:$U$11)) -> FALSE | AH7: =IF(OR(ISBLANK(S1_Input_Raw!C7),ISBLANK(S1_Input_Raw!D7),ISBLANK(S1_Input_Raw!F7)),FALSE(),AND(AE7,OR(AF7,AG7))) -> FALSE | AI7: =IF(OR(ISBLANK(S1_Input_Raw!C7),ISBLANK(S1_Input_Raw!D7),ISBLANK(S1_Input_Raw!F7)),"",IF(S1_Input_Raw!R7="",G7,S1_Input_Raw!R7)) -> 40 | AJ7: =IF(OR(ISBLANK(S1_Input_Raw!C7),ISBLANK(S1_Input_Raw!D7),ISBLANK(S1_Input_Raw!F7)),"",IFERROR(AI7/M7,"")) -> 20 | AK7: =IF(OR(ISBLANK(S1_Input_Raw!C7),ISBLANK(S1_Input_Raw!D7),ISBLANK(S1_Input_Raw!F7)),"",IF(S1_Input_Raw!R7="",0,AI7-G7)) -> -3 | AL7: =IF(OR(ISBLANK(S1_Input_Raw!C7),ISBLANK(S1_Input_Raw!D7),ISBLANK(S1_Input_Raw!F7)),"미모니터링","모니터링됨") -> 모니터링됨 | AM7: =IF(OR(ISBLANK(S1_Input_Raw!C7),ISBLANK(S1_Input_Raw!D7),ISBLANK(S1_Input_Raw!F7)),"",IF(G7<0,"⚠ TIB가 SOL+TST보다 작음 — 취침·기상시각 확인 필요","정상")) -> 정상 | AN7: =IF(OR(ISBLANK(S1_Input_Raw!C7),ISBLANK(S1_Input_Raw!D7),ISBLANK(S1_Input_Raw!F7)),"",IF(S1_Input_Raw!S7="","",S1_Input_Raw!S7)) -> 84 | AO7: =IF(OR(ISBLANK(S1_Input_Raw!C7),ISBLANK(S1_Input_Raw!D7),ISBLANK(S1_Input_Raw!F7)),"",IF(AN7="","",H7-AN7)) -> -0.90140845 | AP7: =IF(OR(ISBLANK(S1_Input_Raw!C7),ISBLANK(S1_Input_Raw!D7),ISBLANK(S1_Input_Raw!F7)),"",IF(AN7="","",IF(ABS(AO7)>=NR_SE_DIFF_REF,"⚠ 차이 큼 — 취침·기상시각 자동감지 방식 차이일 수 있음","일치"))) -> 일치 | AQ7: =IF(OR(ISBLANK(S1_Input_Raw!C7),ISBLANK(S1_Input_Raw!D7),ISBLANK(S1_Input_Raw!F7)),"",IF(AN7="",H7,AN7)) -> 84
A8: =S1_Input_Raw!A8 -> 목 | B8: =S1_Input_Raw!B8 -> 46276 | C8: =IF(OR(ISBLANK(S1_Input_Raw!C8),ISBLANK(S1_Input_Raw!D8),ISBLANK(S1_Input_Raw!F8)),"",IF(S1_Input_Raw!C8>=0.5,(S1_Input_Raw!C8-1)*1440,S1_Input_Raw!C8*1440)) -> 35 | D8: =IF(OR(ISBLANK(S1_Input_Raw!C8),ISBLANK(S1_Input_Raw!D8),ISBLANK(S1_Input_Raw!F8)),"",S1_Input_Raw!D8*1440) -> 405 | E8: =IF(OR(ISBLANK(S1_Input_Raw!C8),ISBLANK(S1_Input_Raw!D8),ISBLANK(S1_Input_Raw!F8)),"",D8-C8) -> 370 | F8: =IF(OR(ISBLANK(S1_Input_Raw!C8),ISBLANK(S1_Input_Raw!D8),ISBLANK(S1_Input_Raw!F8)),"",S1_Input_Raw!F8+S1_Input_Raw!G8+S1_Input_Raw!H8) -> 274 | G8: =IF(OR(ISBLANK(S1_Input_Raw!C8),ISBLANK(S1_Input_Raw!D8),ISBLANK(S1_Input_Raw!F8)),"",E8-S1_Input_Raw!E8-F8) -> 64 | H8: =IF(OR(ISBLANK(S1_Input_Raw!C8),ISBLANK(S1_Input_Raw!D8),ISBLANK(S1_Input_Raw!F8)),"",IFERROR(F8/E8*100,"")) -> 74.054054 | I8: =IF(OR(ISBLANK(S1_Input_Raw!C8),ISBLANK(S1_Input_Raw!D8),ISBLANK(S1_Input_Raw!F8)),"",IFERROR(S1_Input_Raw!F8/F8*100,"")) -> 13.138686 | J8: =IF(OR(ISBLANK(S1_Input_Raw!C8),ISBLANK(S1_Input_Raw!D8),ISBLANK(S1_Input_Raw!F8)),"",IFERROR(S1_Input_Raw!G8/F8*100,"")) -> 60.948905 | K8: =IF(OR(ISBLANK(S1_Input_Raw!C8),ISBLANK(S1_Input_Raw!D8),ISBLANK(S1_Input_Raw!F8)),"",IFERROR(S1_Input_Raw!H8/F8*100,"")) -> 25.912409 | L8: =IF(OR(ISBLANK(S1_Input_Raw!C8),ISBLANK(S1_Input_Raw!D8),ISBLANK(S1_Input_Raw!F8)),"",S1_Input_Raw!E8) -> 32 | M8: =IF(OR(ISBLANK(S1_Input_Raw!C8),ISBLANK(S1_Input_Raw!D8),ISBLANK(S1_Input_Raw!F8)),"",S1_Input_Raw!I8) -> 3 | N8: =IF(OR(ISBLANK(S1_Input_Raw!C8),ISBLANK(S1_Input_Raw!D8),ISBLANK(S1_Input_Raw!F8)),"",S1_Input_Raw!J8) -> 60 | O8: =IF(OR(ISBLANK(S1_Input_Raw!C8),ISBLANK(S1_Input_Raw!D8),ISBLANK(S1_Input_Raw!F8)),"",S1_Input_Raw!K8) -> 16 | P8: =IF(OR(ISBLANK(S1_Input_Raw!C8),ISBLANK(S1_Input_Raw!D8),ISBLANK(S1_Input_Raw!F8)),"",S1_Input_Raw!L8) -> 96 | Q8: =IF(OR(ISBLANK(S1_Input_Raw!C8),ISBLANK(S1_Input_Raw!D8),ISBLANK(S1_Input_Raw!F8)),"",S1_Input_Raw!M8) -> 95 | R8: =IF(OR(ISBLANK(S1_Input_Raw!C8),ISBLANK(S1_Input_Raw!D8),ISBLANK(S1_Input_Raw!F8)),"",S1_Input_Raw!N8) -> 24 | S8: =IF(OR(ISBLANK(S1_Input_Raw!C8),ISBLANK(S1_Input_Raw!D8),ISBLANK(S1_Input_Raw!F8)),"",S1_Input_Raw!O8) -> 3648 | T8: =IF(OR(ISBLANK(S1_Input_Raw!C8),ISBLANK(S1_Input_Raw!D8),ISBLANK(S1_Input_Raw!F8)),"",S1_Input_Raw!P8) -> 1540 | U8: =IF(OR(ISBLANK(S1_Input_Raw!C8),ISBLANK(S1_Input_Raw!D8),ISBLANK(S1_Input_Raw!F8)),"",S1_Input_Raw!Q8) -> 60 | V8: =IF(OR(ISBLANK(S1_Input_Raw!C8),ISBLANK(S1_Input_Raw!D8),ISBLANK(S1_Input_Raw!F8)),"",NR_BMR) -> 1206.5 | W8: =IF(OR(ISBLANK(S1_Input_Raw!C8),ISBLANK(S1_Input_Raw!D8),ISBLANK(S1_Input_Raw!F8)),"",IFERROR(NR_MET*3.5*NR_WEIGHT/200*R8,"")) -> 97.44 | X8: =IF(OR(ISBLANK(S1_Input_Raw!C8),ISBLANK(S1_Input_Raw!D8),ISBLANK(S1_Input_Raw!F8)),"",IFERROR(V8+W8,"")) -> 1303.94 | Y8: =IF(OR(ISBLANK(S1_Input_Raw!C8),ISBLANK(S1_Input_Raw!D8),ISBLANK(S1_Input_Raw!F8)),"",IFERROR(T8-X8,"")) -> 236.06 | Z8: =IF(OR(ISBLANK(S1_Input_Raw!C8),ISBLANK(S1_Input_Raw!D8),ISBLANK(S1_Input_Raw!F8)),"",IF(AND(L8>NR_SOL_REF,M8>NR_AWAKE_REF,AQ8<NR_SE_REF),"복합형(잠들기어려움+자주깨어남)",IF(AND(L8<=NR_SOL_REF,M8>NR_AWAKE_REF),"자주깨어남형",IF(AND(L8>NR_SOL_REF,M8<=NR_AWAKE_REF),"잠들기어려움형","양호")))) -> 복합형(잠들기어려움+자주깨어남) | AA8: =IF(OR(ISBLANK(S1_Input_Raw!C8),ISBLANK(S1_Input_Raw!D8),ISBLANK(S1_Input_Raw!F8)),"",IFERROR(IF(R8<=PERCENTILE($R$5:$R$11,1/3),"저활동",IF(R8<=PERCENTILE($R$5:$R$11,2/3),"중활동","고활동")),"")) -> 저활동 | AB8: =IF(OR(ISBLANK(S1_Input_Raw!C8),ISBLANK(S1_Input_Raw!D8),ISBLANK(S1_Input_Raw!F8)),"",N8-AVERAGE($N$5:$N$11)) -> 0.28571429 | AC8: =IF(OR(ISBLANK(S1_Input_Raw!C8),ISBLANK(S1_Input_Raw!D8),ISBLANK(S1_Input_Raw!F8)),"",O8-AVERAGE($O$5:$O$11)) -> 0.28571429 | AD8: =IF(OR(ISBLANK(S1_Input_Raw!C8),ISBLANK(S1_Input_Raw!D8),ISBLANK(S1_Input_Raw!F8)),"",AVERAGE($P$5:$P$11)-P8) -> 0.28571429 | AE8: =IF(OR(ISBLANK(S1_Input_Raw!C8),ISBLANK(S1_Input_Raw!D8),ISBLANK(S1_Input_Raw!F8)),FALSE(),AND(AB8>=NR_DEV_HR,AC8>=NR_DEV_RR,AD8>=NR_DEV_SPO2)) -> FALSE | AF8: =IF(OR(ISBLANK(S1_Input_Raw!C8),ISBLANK(S1_Input_Raw!D8),ISBLANK(S1_Input_Raw!F8)),FALSE(),R8=MIN($R$5:$R$11)) -> FALSE | AG8: =IF(OR(ISBLANK(S1_Input_Raw!C8),ISBLANK(S1_Input_Raw!D8),ISBLANK(S1_Input_Raw!F8)),FALSE(),U8=MIN($U$5:$U$11)) -> FALSE | AH8: =IF(OR(ISBLANK(S1_Input_Raw!C8),ISBLANK(S1_Input_Raw!D8),ISBLANK(S1_Input_Raw!F8)),FALSE(),AND(AE8,OR(AF8,AG8))) -> FALSE | AI8: =IF(OR(ISBLANK(S1_Input_Raw!C8),ISBLANK(S1_Input_Raw!D8),ISBLANK(S1_Input_Raw!F8)),"",IF(S1_Input_Raw!R8="",G8,S1_Input_Raw!R8)) -> 69 | AJ8: =IF(OR(ISBLANK(S1_Input_Raw!C8),ISBLANK(S1_Input_Raw!D8),ISBLANK(S1_Input_Raw!F8)),"",IFERROR(AI8/M8,"")) -> 23 | AK8: =IF(OR(ISBLANK(S1_Input_Raw!C8),ISBLANK(S1_Input_Raw!D8),ISBLANK(S1_Input_Raw!F8)),"",IF(S1_Input_Raw!R8="",0,AI8-G8)) -> 5 | AL8: =IF(OR(ISBLANK(S1_Input_Raw!C8),ISBLANK(S1_Input_Raw!D8),ISBLANK(S1_Input_Raw!F8)),"미모니터링","모니터링됨") -> 모니터링됨 | AM8: =IF(OR(ISBLANK(S1_Input_Raw!C8),ISBLANK(S1_Input_Raw!D8),ISBLANK(S1_Input_Raw!F8)),"",IF(G8<0,"⚠ TIB가 SOL+TST보다 작음 — 취침·기상시각 확인 필요","정상")) -> 정상 | AN8: =IF(OR(ISBLANK(S1_Input_Raw!C8),ISBLANK(S1_Input_Raw!D8),ISBLANK(S1_Input_Raw!F8)),"",IF(S1_Input_Raw!S8="","",S1_Input_Raw!S8)) -> 65 | AO8: =IF(OR(ISBLANK(S1_Input_Raw!C8),ISBLANK(S1_Input_Raw!D8),ISBLANK(S1_Input_Raw!F8)),"",IF(AN8="","",H8-AN8)) -> 9.0540541 | AP8: =IF(OR(ISBLANK(S1_Input_Raw!C8),ISBLANK(S1_Input_Raw!D8),ISBLANK(S1_Input_Raw!F8)),"",IF(AN8="","",IF(ABS(AO8)>=NR_SE_DIFF_REF,"⚠ 차이 큼 — 취침·기상시각 자동감지 방식 차이일 수 있음","일치"))) -> ⚠ 차이 큼 — 취침·기상시각 자동감지 방식 차이일 수 있음 | AQ8: =IF(OR(ISBLANK(S1_Input_Raw!C8),ISBLANK(S1_Input_Raw!D8),ISBLANK(S1_Input_Raw!F8)),"",IF(AN8="",H8,AN8)) -> 65
A9: =S1_Input_Raw!A9 -> 금 | B9: =S1_Input_Raw!B9 -> 46277 | C9: =IF(OR(ISBLANK(S1_Input_Raw!C9),ISBLANK(S1_Input_Raw!D9),ISBLANK(S1_Input_Raw!F9)),"",IF(S1_Input_Raw!C9>=0.5,(S1_Input_Raw!C9-1)*1440,S1_Input_Raw!C9*1440)) -> 65 | D9: =IF(OR(ISBLANK(S1_Input_Raw!C9),ISBLANK(S1_Input_Raw!D9),ISBLANK(S1_Input_Raw!F9)),"",S1_Input_Raw!D9*1440) -> 380 | E9: =IF(OR(ISBLANK(S1_Input_Raw!C9),ISBLANK(S1_Input_Raw!D9),ISBLANK(S1_Input_Raw!F9)),"",D9-C9) -> 315 | F9: =IF(OR(ISBLANK(S1_Input_Raw!C9),ISBLANK(S1_Input_Raw!D9),ISBLANK(S1_Input_Raw!F9)),"",S1_Input_Raw!F9+S1_Input_Raw!G9+S1_Input_Raw!H9) -> 214 | G9: =IF(OR(ISBLANK(S1_Input_Raw!C9),ISBLANK(S1_Input_Raw!D9),ISBLANK(S1_Input_Raw!F9)),"",E9-S1_Input_Raw!E9-F9) -> 67 | H9: =IF(OR(ISBLANK(S1_Input_Raw!C9),ISBLANK(S1_Input_Raw!D9),ISBLANK(S1_Input_Raw!F9)),"",IFERROR(F9/E9*100,"")) -> 67.936508 | I9: =IF(OR(ISBLANK(S1_Input_Raw!C9),ISBLANK(S1_Input_Raw!D9),ISBLANK(S1_Input_Raw!F9)),"",IFERROR(S1_Input_Raw!F9/F9*100,"")) -> 8.8785047 | J9: =IF(OR(ISBLANK(S1_Input_Raw!C9),ISBLANK(S1_Input_Raw!D9),ISBLANK(S1_Input_Raw!F9)),"",IFERROR(S1_Input_Raw!G9/F9*100,"")) -> 65.88785 | K9: =IF(OR(ISBLANK(S1_Input_Raw!C9),ISBLANK(S1_Input_Raw!D9),ISBLANK(S1_Input_Raw!F9)),"",IFERROR(S1_Input_Raw!H9/F9*100,"")) -> 25.233645 | L9: =IF(OR(ISBLANK(S1_Input_Raw!C9),ISBLANK(S1_Input_Raw!D9),ISBLANK(S1_Input_Raw!F9)),"",S1_Input_Raw!E9) -> 34 | M9: =IF(OR(ISBLANK(S1_Input_Raw!C9),ISBLANK(S1_Input_Raw!D9),ISBLANK(S1_Input_Raw!F9)),"",S1_Input_Raw!I9) -> 4 | N9: =IF(OR(ISBLANK(S1_Input_Raw!C9),ISBLANK(S1_Input_Raw!D9),ISBLANK(S1_Input_Raw!F9)),"",S1_Input_Raw!J9) -> 71 | O9: =IF(OR(ISBLANK(S1_Input_Raw!C9),ISBLANK(S1_Input_Raw!D9),ISBLANK(S1_Input_Raw!F9)),"",S1_Input_Raw!K9) -> 19 | P9: =IF(OR(ISBLANK(S1_Input_Raw!C9),ISBLANK(S1_Input_Raw!D9),ISBLANK(S1_Input_Raw!F9)),"",S1_Input_Raw!L9) -> 93 | Q9: =IF(OR(ISBLANK(S1_Input_Raw!C9),ISBLANK(S1_Input_Raw!D9),ISBLANK(S1_Input_Raw!F9)),"",S1_Input_Raw!M9) -> 92 | R9: =IF(OR(ISBLANK(S1_Input_Raw!C9),ISBLANK(S1_Input_Raw!D9),ISBLANK(S1_Input_Raw!F9)),"",S1_Input_Raw!N9) -> 18 | S9: =IF(OR(ISBLANK(S1_Input_Raw!C9),ISBLANK(S1_Input_Raw!D9),ISBLANK(S1_Input_Raw!F9)),"",S1_Input_Raw!O9) -> 2736 | T9: =IF(OR(ISBLANK(S1_Input_Raw!C9),ISBLANK(S1_Input_Raw!D9),ISBLANK(S1_Input_Raw!F9)),"",S1_Input_Raw!P9) -> 1490 | U9: =IF(OR(ISBLANK(S1_Input_Raw!C9),ISBLANK(S1_Input_Raw!D9),ISBLANK(S1_Input_Raw!F9)),"",S1_Input_Raw!Q9) -> 50 | V9: =IF(OR(ISBLANK(S1_Input_Raw!C9),ISBLANK(S1_Input_Raw!D9),ISBLANK(S1_Input_Raw!F9)),"",NR_BMR) -> 1206.5 | W9: =IF(OR(ISBLANK(S1_Input_Raw!C9),ISBLANK(S1_Input_Raw!D9),ISBLANK(S1_Input_Raw!F9)),"",IFERROR(NR_MET*3.5*NR_WEIGHT/200*R9,"")) -> 73.08 | X9: =IF(OR(ISBLANK(S1_Input_Raw!C9),ISBLANK(S1_Input_Raw!D9),ISBLANK(S1_Input_Raw!F9)),"",IFERROR(V9+W9,"")) -> 1279.58 | Y9: =IF(OR(ISBLANK(S1_Input_Raw!C9),ISBLANK(S1_Input_Raw!D9),ISBLANK(S1_Input_Raw!F9)),"",IFERROR(T9-X9,"")) -> 210.42 | Z9: =IF(OR(ISBLANK(S1_Input_Raw!C9),ISBLANK(S1_Input_Raw!D9),ISBLANK(S1_Input_Raw!F9)),"",IF(AND(L9>NR_SOL_REF,M9>NR_AWAKE_REF,AQ9<NR_SE_REF),"복합형(잠들기어려움+자주깨어남)",IF(AND(L9<=NR_SOL_REF,M9>NR_AWAKE_REF),"자주깨어남형",IF(AND(L9>NR_SOL_REF,M9<=NR_AWAKE_REF),"잠들기어려움형","양호")))) -> 복합형(잠들기어려움+자주깨어남) | AA9: =IF(OR(ISBLANK(S1_Input_Raw!C9),ISBLANK(S1_Input_Raw!D9),ISBLANK(S1_Input_Raw!F9)),"",IFERROR(IF(R9<=PERCENTILE($R$5:$R$11,1/3),"저활동",IF(R9<=PERCENTILE($R$5:$R$11,2/3),"중활동","고활동")),"")) -> 저활동 | AB9: =IF(OR(ISBLANK(S1_Input_Raw!C9),ISBLANK(S1_Input_Raw!D9),ISBLANK(S1_Input_Raw!F9)),"",N9-AVERAGE($N$5:$N$11)) -> 11.285714 | AC9: =IF(OR(ISBLANK(S1_Input_Raw!C9),ISBLANK(S1_Input_Raw!D9),ISBLANK(S1_Input_Raw!F9)),"",O9-AVERAGE($O$5:$O$11)) -> 3.2857143 | AD9: =IF(OR(ISBLANK(S1_Input_Raw!C9),ISBLANK(S1_Input_Raw!D9),ISBLANK(S1_Input_Raw!F9)),"",AVERAGE($P$5:$P$11)-P9) -> 3.2857143 | AE9: =IF(OR(ISBLANK(S1_Input_Raw!C9),ISBLANK(S1_Input_Raw!D9),ISBLANK(S1_Input_Raw!F9)),FALSE(),AND(AB9>=NR_DEV_HR,AC9>=NR_DEV_RR,AD9>=NR_DEV_SPO2)) -> TRUE | AF9: =IF(OR(ISBLANK(S1_Input_Raw!C9),ISBLANK(S1_Input_Raw!D9),ISBLANK(S1_Input_Raw!F9)),FALSE(),R9=MIN($R$5:$R$11)) -> TRUE | AG9: =IF(OR(ISBLANK(S1_Input_Raw!C9),ISBLANK(S1_Input_Raw!D9),ISBLANK(S1_Input_Raw!F9)),FALSE(),U9=MIN($U$5:$U$11)) -> TRUE | AH9: =IF(OR(ISBLANK(S1_Input_Raw!C9),ISBLANK(S1_Input_Raw!D9),ISBLANK(S1_Input_Raw!F9)),FALSE(),AND(AE9,OR(AF9,AG9))) -> TRUE | AI9: =IF(OR(ISBLANK(S1_Input_Raw!C9),ISBLANK(S1_Input_Raw!D9),ISBLANK(S1_Input_Raw!F9)),"",IF(S1_Input_Raw!R9="",G9,S1_Input_Raw!R9)) -> 63 | AJ9: =IF(OR(ISBLANK(S1_Input_Raw!C9),ISBLANK(S1_Input_Raw!D9),ISBLANK(S1_Input_Raw!F9)),"",IFERROR(AI9/M9,"")) -> 15.75 | AK9: =IF(OR(ISBLANK(S1_Input_Raw!C9),ISBLANK(S1_Input_Raw!D9),ISBLANK(S1_Input_Raw!F9)),"",IF(S1_Input_Raw!R9="",0,AI9-G9)) -> -4 | AL9: =IF(OR(ISBLANK(S1_Input_Raw!C9),ISBLANK(S1_Input_Raw!D9),ISBLANK(S1_Input_Raw!F9)),"미모니터링","모니터링됨") -> 모니터링됨 | AM9: =IF(OR(ISBLANK(S1_Input_Raw!C9),ISBLANK(S1_Input_Raw!D9),ISBLANK(S1_Input_Raw!F9)),"",IF(G9<0,"⚠ TIB가 SOL+TST보다 작음 — 취침·기상시각 확인 필요","정상")) -> 정상 | AN9: =IF(OR(ISBLANK(S1_Input_Raw!C9),ISBLANK(S1_Input_Raw!D9),ISBLANK(S1_Input_Raw!F9)),"",IF(S1_Input_Raw!S9="","",S1_Input_Raw!S9)) -> 66 | AO9: =IF(OR(ISBLANK(S1_Input_Raw!C9),ISBLANK(S1_Input_Raw!D9),ISBLANK(S1_Input_Raw!F9)),"",IF(AN9="","",H9-AN9)) -> 1.9365079 | AP9: =IF(OR(ISBLANK(S1_Input_Raw!C9),ISBLANK(S1_Input_Raw!D9),ISBLANK(S1_Input_Raw!F9)),"",IF(AN9="","",IF(ABS(AO9)>=NR_SE_DIFF_REF,"⚠ 차이 큼 — 취침·기상시각 자동감지 방식 차이일 수 있음","일치"))) -> 일치 | AQ9: =IF(OR(ISBLANK(S1_Input_Raw!C9),ISBLANK(S1_Input_Raw!D9),ISBLANK(S1_Input_Raw!F9)),"",IF(AN9="",H9,AN9)) -> 66
A10: =S1_Input_Raw!A10 -> 토 | B10: =S1_Input_Raw!B10 -> 46278 | C10: =IF(OR(ISBLANK(S1_Input_Raw!C10),ISBLANK(S1_Input_Raw!D10),ISBLANK(S1_Input_Raw!F10)),"",IF(S1_Input_Raw!C10>=0.5,(S1_Input_Raw!C10-1)*1440,S1_Input_Raw!C10*1440)) -> -45 | D10: =IF(OR(ISBLANK(S1_Input_Raw!C10),ISBLANK(S1_Input_Raw!D10),ISBLANK(S1_Input_Raw!F10)),"",S1_Input_Raw!D10*1440) -> 425 | E10: =IF(OR(ISBLANK(S1_Input_Raw!C10),ISBLANK(S1_Input_Raw!D10),ISBLANK(S1_Input_Raw!F10)),"",D10-C10) -> 470 | F10: =IF(OR(ISBLANK(S1_Input_Raw!C10),ISBLANK(S1_Input_Raw!D10),ISBLANK(S1_Input_Raw!F10)),"",S1_Input_Raw!F10+S1_Input_Raw!G10+S1_Input_Raw!H10) -> 400 | G10: =IF(OR(ISBLANK(S1_Input_Raw!C10),ISBLANK(S1_Input_Raw!D10),ISBLANK(S1_Input_Raw!F10)),"",E10-S1_Input_Raw!E10-F10) -> 55 | H10: =IF(OR(ISBLANK(S1_Input_Raw!C10),ISBLANK(S1_Input_Raw!D10),ISBLANK(S1_Input_Raw!F10)),"",IFERROR(F10/E10*100,"")) -> 85.106383 | I10: =IF(OR(ISBLANK(S1_Input_Raw!C10),ISBLANK(S1_Input_Raw!D10),ISBLANK(S1_Input_Raw!F10)),"",IFERROR(S1_Input_Raw!F10/F10*100,"")) -> 22 | J10: =IF(OR(ISBLANK(S1_Input_Raw!C10),ISBLANK(S1_Input_Raw!D10),ISBLANK(S1_Input_Raw!F10)),"",IFERROR(S1_Input_Raw!G10/F10*100,"")) -> 48 | K10: =IF(OR(ISBLANK(S1_Input_Raw!C10),ISBLANK(S1_Input_Raw!D10),ISBLANK(S1_Input_Raw!F10)),"",IFERROR(S1_Input_Raw!H10/F10*100,"")) -> 30 | L10: =IF(OR(ISBLANK(S1_Input_Raw!C10),ISBLANK(S1_Input_Raw!D10),ISBLANK(S1_Input_Raw!F10)),"",S1_Input_Raw!E10) -> 15 | M10: =IF(OR(ISBLANK(S1_Input_Raw!C10),ISBLANK(S1_Input_Raw!D10),ISBLANK(S1_Input_Raw!F10)),"",S1_Input_Raw!I10) -> 2 | N10: =IF(OR(ISBLANK(S1_Input_Raw!C10),ISBLANK(S1_Input_Raw!D10),ISBLANK(S1_Input_Raw!F10)),"",S1_Input_Raw!J10) -> 55 | O10: =IF(OR(ISBLANK(S1_Input_Raw!C10),ISBLANK(S1_Input_Raw!D10),ISBLANK(S1_Input_Raw!F10)),"",S1_Input_Raw!K10) -> 14 | P10: =IF(OR(ISBLANK(S1_Input_Raw!C10),ISBLANK(S1_Input_Raw!D10),ISBLANK(S1_Input_Raw!F10)),"",S1_Input_Raw!L10) -> 98 | Q10: =IF(OR(ISBLANK(S1_Input_Raw!C10),ISBLANK(S1_Input_Raw!D10),ISBLANK(S1_Input_Raw!F10)),"",S1_Input_Raw!M10) -> 97 | R10: =IF(OR(ISBLANK(S1_Input_Raw!C10),ISBLANK(S1_Input_Raw!D10),ISBLANK(S1_Input_Raw!F10)),"",S1_Input_Raw!N10) -> 62 | S10: =IF(OR(ISBLANK(S1_Input_Raw!C10),ISBLANK(S1_Input_Raw!D10),ISBLANK(S1_Input_Raw!F10)),"",S1_Input_Raw!O10) -> 9424 | T10: =IF(OR(ISBLANK(S1_Input_Raw!C10),ISBLANK(S1_Input_Raw!D10),ISBLANK(S1_Input_Raw!F10)),"",S1_Input_Raw!P10) -> 1780 | U10: =IF(OR(ISBLANK(S1_Input_Raw!C10),ISBLANK(S1_Input_Raw!D10),ISBLANK(S1_Input_Raw!F10)),"",S1_Input_Raw!Q10) -> 74 | V10: =IF(OR(ISBLANK(S1_Input_Raw!C10),ISBLANK(S1_Input_Raw!D10),ISBLANK(S1_Input_Raw!F10)),"",NR_BMR) -> 1206.5 | W10: =IF(OR(ISBLANK(S1_Input_Raw!C10),ISBLANK(S1_Input_Raw!D10),ISBLANK(S1_Input_Raw!F10)),"",IFERROR(NR_MET*3.5*NR_WEIGHT/200*R10,"")) -> 251.72 | X10: =IF(OR(ISBLANK(S1_Input_Raw!C10),ISBLANK(S1_Input_Raw!D10),ISBLANK(S1_Input_Raw!F10)),"",IFERROR(V10+W10,"")) -> 1458.22 | Y10: =IF(OR(ISBLANK(S1_Input_Raw!C10),ISBLANK(S1_Input_Raw!D10),ISBLANK(S1_Input_Raw!F10)),"",IFERROR(T10-X10,"")) -> 321.78 | Z10: =IF(OR(ISBLANK(S1_Input_Raw!C10),ISBLANK(S1_Input_Raw!D10),ISBLANK(S1_Input_Raw!F10)),"",IF(AND(L10>NR_SOL_REF,M10>NR_AWAKE_REF,AQ10<NR_SE_REF),"복합형(잠들기어려움+자주깨어남)",IF(AND(L10<=NR_SOL_REF,M10>NR_AWAKE_REF),"자주깨어남형",IF(AND(L10>NR_SOL_REF,M10<=NR_AWAKE_REF),"잠들기어려움형","양호")))) -> 양호 | AA10: =IF(OR(ISBLANK(S1_Input_Raw!C10),ISBLANK(S1_Input_Raw!D10),ISBLANK(S1_Input_Raw!F10)),"",IFERROR(IF(R10<=PERCENTILE($R$5:$R$11,1/3),"저활동",IF(R10<=PERCENTILE($R$5:$R$11,2/3),"중활동","고활동")),"")) -> 고활동 | AB10: =IF(OR(ISBLANK(S1_Input_Raw!C10),ISBLANK(S1_Input_Raw!D10),ISBLANK(S1_Input_Raw!F10)),"",N10-AVERAGE($N$5:$N$11)) -> -4.7142857 | AC10: =IF(OR(ISBLANK(S1_Input_Raw!C10),ISBLANK(S1_Input_Raw!D10),ISBLANK(S1_Input_Raw!F10)),"",O10-AVERAGE($O$5:$O$11)) -> -1.7142857 | AD10: =IF(OR(ISBLANK(S1_Input_Raw!C10),ISBLANK(S1_Input_Raw!D10),ISBLANK(S1_Input_Raw!F10)),"",AVERAGE($P$5:$P$11)-P10) -> -1.7142857 | AE10: =IF(OR(ISBLANK(S1_Input_Raw!C10),ISBLANK(S1_Input_Raw!D10),ISBLANK(S1_Input_Raw!F10)),FALSE(),AND(AB10>=NR_DEV_HR,AC10>=NR_DEV_RR,AD10>=NR_DEV_SPO2)) -> FALSE | AF10: =IF(OR(ISBLANK(S1_Input_Raw!C10),ISBLANK(S1_Input_Raw!D10),ISBLANK(S1_Input_Raw!F10)),FALSE(),R10=MIN($R$5:$R$11)) -> FALSE | AG10: =IF(OR(ISBLANK(S1_Input_Raw!C10),ISBLANK(S1_Input_Raw!D10),ISBLANK(S1_Input_Raw!F10)),FALSE(),U10=MIN($U$5:$U$11)) -> FALSE | AH10: =IF(OR(ISBLANK(S1_Input_Raw!C10),ISBLANK(S1_Input_Raw!D10),ISBLANK(S1_Input_Raw!F10)),FALSE(),AND(AE10,OR(AF10,AG10))) -> FALSE | AI10: =IF(OR(ISBLANK(S1_Input_Raw!C10),ISBLANK(S1_Input_Raw!D10),ISBLANK(S1_Input_Raw!F10)),"",IF(S1_Input_Raw!R10="",G10,S1_Input_Raw!R10)) -> 58 | AJ10: =IF(OR(ISBLANK(S1_Input_Raw!C10),ISBLANK(S1_Input_Raw!D10),ISBLANK(S1_Input_Raw!F10)),"",IFERROR(AI10/M10,"")) -> 29 | AK10: =IF(OR(ISBLANK(S1_Input_Raw!C10),ISBLANK(S1_Input_Raw!D10),ISBLANK(S1_Input_Raw!F10)),"",IF(S1_Input_Raw!R10="",0,AI10-G10)) -> 3 | AL10: =IF(OR(ISBLANK(S1_Input_Raw!C10),ISBLANK(S1_Input_Raw!D10),ISBLANK(S1_Input_Raw!F10)),"미모니터링","모니터링됨") -> 모니터링됨 | AM10: =IF(OR(ISBLANK(S1_Input_Raw!C10),ISBLANK(S1_Input_Raw!D10),ISBLANK(S1_Input_Raw!F10)),"",IF(G10<0,"⚠ TIB가 SOL+TST보다 작음 — 취침·기상시각 확인 필요","정상")) -> 정상 | AN10: =IF(OR(ISBLANK(S1_Input_Raw!C10),ISBLANK(S1_Input_Raw!D10),ISBLANK(S1_Input_Raw!F10)),"",IF(S1_Input_Raw!S10="","",S1_Input_Raw!S10)) -> 83 | AO10: =IF(OR(ISBLANK(S1_Input_Raw!C10),ISBLANK(S1_Input_Raw!D10),ISBLANK(S1_Input_Raw!F10)),"",IF(AN10="","",H10-AN10)) -> 2.106383 | AP10: =IF(OR(ISBLANK(S1_Input_Raw!C10),ISBLANK(S1_Input_Raw!D10),ISBLANK(S1_Input_Raw!F10)),"",IF(AN10="","",IF(ABS(AO10)>=NR_SE_DIFF_REF,"⚠ 차이 큼 — 취침·기상시각 자동감지 방식 차이일 수 있음","일치"))) -> 일치 | AQ10: =IF(OR(ISBLANK(S1_Input_Raw!C10),ISBLANK(S1_Input_Raw!D10),ISBLANK(S1_Input_Raw!F10)),"",IF(AN10="",H10,AN10)) -> 83
A11: =S1_Input_Raw!A11 -> 일 | B11: =S1_Input_Raw!B11 -> 46279 | C11: =IF(OR(ISBLANK(S1_Input_Raw!C11),ISBLANK(S1_Input_Raw!D11),ISBLANK(S1_Input_Raw!F11)),"",IF(S1_Input_Raw!C11>=0.5,(S1_Input_Raw!C11-1)*1440,S1_Input_Raw!C11*1440)) -> -5 | D11: =IF(OR(ISBLANK(S1_Input_Raw!C11),ISBLANK(S1_Input_Raw!D11),ISBLANK(S1_Input_Raw!F11)),"",S1_Input_Raw!D11*1440) -> 415 | E11: =IF(OR(ISBLANK(S1_Input_Raw!C11),ISBLANK(S1_Input_Raw!D11),ISBLANK(S1_Input_Raw!F11)),"",D11-C11) -> 420 | F11: =IF(OR(ISBLANK(S1_Input_Raw!C11),ISBLANK(S1_Input_Raw!D11),ISBLANK(S1_Input_Raw!F11)),"",S1_Input_Raw!F11+S1_Input_Raw!G11+S1_Input_Raw!H11) -> 344 | G11: =IF(OR(ISBLANK(S1_Input_Raw!C11),ISBLANK(S1_Input_Raw!D11),ISBLANK(S1_Input_Raw!F11)),"",E11-S1_Input_Raw!E11-F11) -> 56 | H11: =IF(OR(ISBLANK(S1_Input_Raw!C11),ISBLANK(S1_Input_Raw!D11),ISBLANK(S1_Input_Raw!F11)),"",IFERROR(F11/E11*100,"")) -> 81.904762 | I11: =IF(OR(ISBLANK(S1_Input_Raw!C11),ISBLANK(S1_Input_Raw!D11),ISBLANK(S1_Input_Raw!F11)),"",IFERROR(S1_Input_Raw!F11/F11*100,"")) -> 18.895349 | J11: =IF(OR(ISBLANK(S1_Input_Raw!C11),ISBLANK(S1_Input_Raw!D11),ISBLANK(S1_Input_Raw!F11)),"",IFERROR(S1_Input_Raw!G11/F11*100,"")) -> 52.906977 | K11: =IF(OR(ISBLANK(S1_Input_Raw!C11),ISBLANK(S1_Input_Raw!D11),ISBLANK(S1_Input_Raw!F11)),"",IFERROR(S1_Input_Raw!H11/F11*100,"")) -> 28.197674 | L11: =IF(OR(ISBLANK(S1_Input_Raw!C11),ISBLANK(S1_Input_Raw!D11),ISBLANK(S1_Input_Raw!F11)),"",S1_Input_Raw!E11) -> 20 | M11: =IF(OR(ISBLANK(S1_Input_Raw!C11),ISBLANK(S1_Input_Raw!D11),ISBLANK(S1_Input_Raw!F11)),"",S1_Input_Raw!I11) -> 3 | N11: =IF(OR(ISBLANK(S1_Input_Raw!C11),ISBLANK(S1_Input_Raw!D11),ISBLANK(S1_Input_Raw!F11)),"",S1_Input_Raw!J11) -> 56 | O11: =IF(OR(ISBLANK(S1_Input_Raw!C11),ISBLANK(S1_Input_Raw!D11),ISBLANK(S1_Input_Raw!F11)),"",S1_Input_Raw!K11) -> 15 | P11: =IF(OR(ISBLANK(S1_Input_Raw!C11),ISBLANK(S1_Input_Raw!D11),ISBLANK(S1_Input_Raw!F11)),"",S1_Input_Raw!L11) -> 97 | Q11: =IF(OR(ISBLANK(S1_Input_Raw!C11),ISBLANK(S1_Input_Raw!D11),ISBLANK(S1_Input_Raw!F11)),"",S1_Input_Raw!M11) -> 96 | R11: =IF(OR(ISBLANK(S1_Input_Raw!C11),ISBLANK(S1_Input_Raw!D11),ISBLANK(S1_Input_Raw!F11)),"",S1_Input_Raw!N11) -> 45 | S11: =IF(OR(ISBLANK(S1_Input_Raw!C11),ISBLANK(S1_Input_Raw!D11),ISBLANK(S1_Input_Raw!F11)),"",S1_Input_Raw!O11) -> 6840 | T11: =IF(OR(ISBLANK(S1_Input_Raw!C11),ISBLANK(S1_Input_Raw!D11),ISBLANK(S1_Input_Raw!F11)),"",S1_Input_Raw!P11) -> 1660 | U11: =IF(OR(ISBLANK(S1_Input_Raw!C11),ISBLANK(S1_Input_Raw!D11),ISBLANK(S1_Input_Raw!F11)),"",S1_Input_Raw!Q11) -> 70 | V11: =IF(OR(ISBLANK(S1_Input_Raw!C11),ISBLANK(S1_Input_Raw!D11),ISBLANK(S1_Input_Raw!F11)),"",NR_BMR) -> 1206.5 | W11: =IF(OR(ISBLANK(S1_Input_Raw!C11),ISBLANK(S1_Input_Raw!D11),ISBLANK(S1_Input_Raw!F11)),"",IFERROR(NR_MET*3.5*NR_WEIGHT/200*R11,"")) -> 182.7 | X11: =IF(OR(ISBLANK(S1_Input_Raw!C11),ISBLANK(S1_Input_Raw!D11),ISBLANK(S1_Input_Raw!F11)),"",IFERROR(V11+W11,"")) -> 1389.2 | Y11: =IF(OR(ISBLANK(S1_Input_Raw!C11),ISBLANK(S1_Input_Raw!D11),ISBLANK(S1_Input_Raw!F11)),"",IFERROR(T11-X11,"")) -> 270.8 | Z11: =IF(OR(ISBLANK(S1_Input_Raw!C11),ISBLANK(S1_Input_Raw!D11),ISBLANK(S1_Input_Raw!F11)),"",IF(AND(L11>NR_SOL_REF,M11>NR_AWAKE_REF,AQ11<NR_SE_REF),"복합형(잠들기어려움+자주깨어남)",IF(AND(L11<=NR_SOL_REF,M11>NR_AWAKE_REF),"자주깨어남형",IF(AND(L11>NR_SOL_REF,M11<=NR_AWAKE_REF),"잠들기어려움형","양호")))) -> 자주깨어남형 | AA11: =IF(OR(ISBLANK(S1_Input_Raw!C11),ISBLANK(S1_Input_Raw!D11),ISBLANK(S1_Input_Raw!F11)),"",IFERROR(IF(R11<=PERCENTILE($R$5:$R$11,1/3),"저활동",IF(R11<=PERCENTILE($R$5:$R$11,2/3),"중활동","고활동")),"")) -> 중활동 | AB11: =IF(OR(ISBLANK(S1_Input_Raw!C11),ISBLANK(S1_Input_Raw!D11),ISBLANK(S1_Input_Raw!F11)),"",N11-AVERAGE($N$5:$N$11)) -> -3.7142857 | AC11: =IF(OR(ISBLANK(S1_Input_Raw!C11),ISBLANK(S1_Input_Raw!D11),ISBLANK(S1_Input_Raw!F11)),"",O11-AVERAGE($O$5:$O$11)) -> -0.71428571 | AD11: =IF(OR(ISBLANK(S1_Input_Raw!C11),ISBLANK(S1_Input_Raw!D11),ISBLANK(S1_Input_Raw!F11)),"",AVERAGE($P$5:$P$11)-P11) -> -0.71428571 | AE11: =IF(OR(ISBLANK(S1_Input_Raw!C11),ISBLANK(S1_Input_Raw!D11),ISBLANK(S1_Input_Raw!F11)),FALSE(),AND(AB11>=NR_DEV_HR,AC11>=NR_DEV_RR,AD11>=NR_DEV_SPO2)) -> FALSE | AF11: =IF(OR(ISBLANK(S1_Input_Raw!C11),ISBLANK(S1_Input_Raw!D11),ISBLANK(S1_Input_Raw!F11)),FALSE(),R11=MIN($R$5:$R$11)) -> FALSE | AG11: =IF(OR(ISBLANK(S1_Input_Raw!C11),ISBLANK(S1_Input_Raw!D11),ISBLANK(S1_Input_Raw!F11)),FALSE(),U11=MIN($U$5:$U$11)) -> FALSE | AH11: =IF(OR(ISBLANK(S1_Input_Raw!C11),ISBLANK(S1_Input_Raw!D11),ISBLANK(S1_Input_Raw!F11)),FALSE(),AND(AE11,OR(AF11,AG11))) -> FALSE | AI11: =IF(OR(ISBLANK(S1_Input_Raw!C11),ISBLANK(S1_Input_Raw!D11),ISBLANK(S1_Input_Raw!F11)),"",IF(S1_Input_Raw!R11="",G11,S1_Input_Raw!R11)) -> 59 | AJ11: =IF(OR(ISBLANK(S1_Input_Raw!C11),ISBLANK(S1_Input_Raw!D11),ISBLANK(S1_Input_Raw!F11)),"",IFERROR(AI11/M11,"")) -> 19.666667 | AK11: =IF(OR(ISBLANK(S1_Input_Raw!C11),ISBLANK(S1_Input_Raw!D11),ISBLANK(S1_Input_Raw!F11)),"",IF(S1_Input_Raw!R11="",0,AI11-G11)) -> 3 | AL11: =IF(OR(ISBLANK(S1_Input_Raw!C11),ISBLANK(S1_Input_Raw!D11),ISBLANK(S1_Input_Raw!F11)),"미모니터링","모니터링됨") -> 모니터링됨 | AM11: =IF(OR(ISBLANK(S1_Input_Raw!C11),ISBLANK(S1_Input_Raw!D11),ISBLANK(S1_Input_Raw!F11)),"",IF(G11<0,"⚠ TIB가 SOL+TST보다 작음 — 취침·기상시각 확인 필요","정상")) -> 정상 | AN11: =IF(OR(ISBLANK(S1_Input_Raw!C11),ISBLANK(S1_Input_Raw!D11),ISBLANK(S1_Input_Raw!F11)),"",IF(S1_Input_Raw!S11="","",S1_Input_Raw!S11)) -> 79 | AO11: =IF(OR(ISBLANK(S1_Input_Raw!C11),ISBLANK(S1_Input_Raw!D11),ISBLANK(S1_Input_Raw!F11)),"",IF(AN11="","",H11-AN11)) -> 2.9047619 | AP11: =IF(OR(ISBLANK(S1_Input_Raw!C11),ISBLANK(S1_Input_Raw!D11),ISBLANK(S1_Input_Raw!F11)),"",IF(AN11="","",IF(ABS(AO11)>=NR_SE_DIFF_REF,"⚠ 차이 큼 — 취침·기상시각 자동감지 방식 차이일 수 있음","일치"))) -> 일치 | AQ11: =IF(OR(ISBLANK(S1_Input_Raw!C11),ISBLANK(S1_Input_Raw!D11),ISBLANK(S1_Input_Raw!F11)),"",IF(AN11="",H11,AN11)) -> 79

Sheet S5_Calc_Weekly
A1: S5. 주간 요약 · 상관관계 · 회귀
A2: 7일 데이터를 바탕으로 평균/범위/변동폭/표준편차/상관계수/회귀기울기를 계산합니다.
A4: ① 지표별 주간 통계
A5: 지표 | B5: 평균 | C5: 최소 | D5: 최대 | E5: 범위(최대-최소) | F5: 표준편차 | G5: 최대값 요일 | H5: 최소값 요일
A6: 총수면시간 (TST, 분) | B6: =IFERROR(AVERAGE(D_TST),"") -> 300.71429 | C6: =IFERROR(MIN(D_TST),"") -> 214 | D6: =IFERROR(MAX(D_TST),"") -> 400 | E6: =IFERROR(D6-C6,"") -> 186 | F6: =IFERROR(STDEV(D_TST),"") -> 58.12548 | G6: =IFERROR(INDEX(D_LABEL,MATCH(D6,D_TST,0)),"") -> 토 | H6: =IFERROR(INDEX(D_LABEL,MATCH(C6,D_TST,0)),"") -> 금
A7: 수면효율 (SE, %) | B7: =IFERROR(AVERAGE(D_SE),"") -> 75.571429 | C7: =IFERROR(MIN(D_SE),"") -> 65 | D7: =IFERROR(MAX(D_SE),"") -> 84 | E7: =IFERROR(D7-C7,"") -> 19 | F7: =IFERROR(STDEV(D_SE),"") -> 7.6345081 | G7: =IFERROR(INDEX(D_LABEL,MATCH(D7,D_SE,0)),"") -> 수 | H7: =IFERROR(INDEX(D_LABEL,MATCH(C7,D_SE,0)),"") -> 목
A8: 입면잠복기 (SOL, 분) | B8: =IFERROR(AVERAGE(D_SOL),"") -> 23.571429 | C8: =IFERROR(MIN(D_SOL),"") -> 15 | D8: =IFERROR(MAX(D_SOL),"") -> 34 | E8: =IFERROR(D8-C8,"") -> 19 | F8: =IFERROR(STDEV(D_SOL),"") -> 7.6345081 | G8: =IFERROR(INDEX(D_LABEL,MATCH(D8,D_SOL,0)),"") -> 금 | H8: =IFERROR(INDEX(D_LABEL,MATCH(C8,D_SOL,0)),"") -> 토
A9: 각성횟수 (회) | B9: =IFERROR(AVERAGE(D_AWAKE),"") -> 2.7142857 | C9: =IFERROR(MIN(D_AWAKE),"") -> 2 | D9: =IFERROR(MAX(D_AWAKE),"") -> 4 | E9: =IFERROR(D9-C9,"") -> 2 | F9: =IFERROR(STDEV(D_AWAKE),"") -> 0.75592895 | G9: =IFERROR(INDEX(D_LABEL,MATCH(D9,D_AWAKE,0)),"") -> 금 | H9: =IFERROR(INDEX(D_LABEL,MATCH(C9,D_AWAKE,0)),"") -> 월
A10: 심박수 (HR, bpm) | B10: =IFERROR(AVERAGE(D_HR),"") -> 59.714286 | C10: =IFERROR(MIN(D_HR),"") -> 55 | D10: =IFERROR(MAX(D_HR),"") -> 71 | E10: =IFERROR(D10-C10,"") -> 16 | F10: =IFERROR(STDEV(D_HR),"") -> 5.4072262 | G10: =IFERROR(INDEX(D_LABEL,MATCH(D10,D_HR,0)),"") -> 금 | H10: =IFERROR(INDEX(D_LABEL,MATCH(C10,D_HR,0)),"") -> 토
A11: 호흡수 (RR, 회/분) | B11: =IFERROR(AVERAGE(D_RR),"") -> 15.714286 | C11: =IFERROR(MIN(D_RR),"") -> 14 | D11: =IFERROR(MAX(D_RR),"") -> 19 | E11: =IFERROR(D11-C11,"") -> 5 | F11: =IFERROR(STDEV(D_RR),"") -> 1.6035675 | G11: =IFERROR(INDEX(D_LABEL,MATCH(D11,D_RR,0)),"") -> 금 | H11: =IFERROR(INDEX(D_LABEL,MATCH(C11,D_RR,0)),"") -> 토
A12: SpO2 (%) | B12: =IFERROR(AVERAGE(D_SPO2),"") -> 96.285714 | C12: =IFERROR(MIN(D_SPO2),"") -> 93 | D12: =IFERROR(MAX(D_SPO2),"") -> 98 | E12: =IFERROR(D12-C12,"") -> 5 | F12: =IFERROR(STDEV(D_SPO2),"") -> 1.6035675 | G12: =IFERROR(INDEX(D_LABEL,MATCH(D12,D_SPO2,0)),"") -> 토 | H12: =IFERROR(INDEX(D_LABEL,MATCH(C12,D_SPO2,0)),"") -> 금
A13: 활동시간 (분) | B13: =IFERROR(AVERAGE(D_ACT),"") -> 39.571429 | C13: =IFERROR(MIN(D_ACT),"") -> 18 | D13: =IFERROR(MAX(D_ACT),"") -> 62 | E13: =IFERROR(D13-C13,"") -> 44 | F13: =IFERROR(STDEV(D_ACT),"") -> 16.112698 | G13: =IFERROR(INDEX(D_LABEL,MATCH(D13,D_ACT,0)),"") -> 토 | H13: =IFERROR(INDEX(D_LABEL,MATCH(C13,D_ACT,0)),"") -> 금
A14: 소모칼로리 - 기기값 (kcal) | B14: =IFERROR(AVERAGE(D_KCAL_DEVICE),"") -> 1631.4286 | C14: =IFERROR(MIN(D_KCAL_DEVICE),"") -> 1490 | D14: =IFERROR(MAX(D_KCAL_DEVICE),"") -> 1780 | E14: =IFERROR(D14-C14,"") -> 290 | F14: =IFERROR(STDEV(D_KCAL_DEVICE),"") -> 101.72325 | G14: =IFERROR(INDEX(D_LABEL,MATCH(D14,D_KCAL_DEVICE,0)),"") -> 토 | H14: =IFERROR(INDEX(D_LABEL,MATCH(C14,D_KCAL_DEVICE,0)),"") -> 금
A15: 활력점수 (0~100) | B15: =IFERROR(AVERAGE(D_VITAL),"") -> 65.428571 | C15: =IFERROR(MIN(D_VITAL),"") -> 50 | D15: =IFERROR(MAX(D_VITAL),"") -> 74 | E15: =IFERROR(D15-C15,"") -> 24 | F15: =IFERROR(STDEV(D_VITAL),"") -> 8.303757 | G15: =IFERROR(INDEX(D_LABEL,MATCH(D15,D_VITAL,0)),"") -> 토 | H15: =IFERROR(INDEX(D_LABEL,MATCH(C15,D_VITAL,0)),"") -> 금
A16: 깊은수면 비율 (%) | B16: =IFERROR(AVERAGE(D_DEEP_PCT),"") -> 16.39235 | C16: =IFERROR(MIN(D_DEEP_PCT),"") -> 8.8785047 | D16: =IFERROR(MAX(D_DEEP_PCT),"") -> 22 | E16: =IFERROR(D16-C16,"") -> 13.121495 | F16: =IFERROR(STDEV(D_DEEP_PCT),"") -> 4.5978739 | G16: =IFERROR(INDEX(D_LABEL,MATCH(D16,D_DEEP_PCT,0)),"") -> 토 | H16: =IFERROR(INDEX(D_LABEL,MATCH(C16,D_DEEP_PCT,0)),"") -> 금
A17: 얕은수면 비율 (%) | B17: =IFERROR(AVERAGE(D_LIGHT_PCT),"") -> 56.404722 | C17: =IFERROR(MIN(D_LIGHT_PCT),"") -> 48 | D17: =IFERROR(MAX(D_LIGHT_PCT),"") -> 65.88785 | E17: =IFERROR(D17-C17,"") -> 17.88785 | F17: =IFERROR(STDEV(D_LIGHT_PCT),"") -> 6.1975032 | G17: =IFERROR(INDEX(D_LABEL,MATCH(D17,D_LIGHT_PCT,0)),"") -> 금 | H17: =IFERROR(INDEX(D_LABEL,MATCH(C17,D_LIGHT_PCT,0)),"") -> 토
A18: 렘수면 비율 (%) | B18: =IFERROR(AVERAGE(D_REM_PCT),"") -> 27.202928 | C18: =IFERROR(MIN(D_REM_PCT),"") -> 25.233645 | D18: =IFERROR(MAX(D_REM_PCT),"") -> 30 | E18: =IFERROR(D18-C18,"") -> 4.7663551 | F18: =IFERROR(STDEV(D_REM_PCT),"") -> 1.6752086 | G18: =IFERROR(INDEX(D_LABEL,MATCH(D18,D_REM_PCT,0)),"") -> 토 | H18: =IFERROR(INDEX(D_LABEL,MATCH(C18,D_REM_PCT,0)),"") -> 금
A19: 각성시간 (실측/추정, 분) | B19: =IFERROR(AVERAGE(D_WASO_DEVICE),"") -> 57 | C19: =IFERROR(MIN(D_WASO_DEVICE),"") -> 40 | D19: =IFERROR(MAX(D_WASO_DEVICE),"") -> 69 | E19: =IFERROR(D19-C19,"") -> 29 | F19: =IFERROR(STDEV(D_WASO_DEVICE),"") -> 10.984838 | G19: =IFERROR(INDEX(D_LABEL,MATCH(D19,D_WASO_DEVICE,0)),"") -> 목 | H19: =IFERROR(INDEX(D_LABEL,MATCH(C19,D_WASO_DEVICE,0)),"") -> 수
A20: 평균 각성 지속시간 (분/1회) | B20: =IFERROR(AVERAGE(D_AVGDUR),"") -> 21.630952 | C20: =IFERROR(MIN(D_AVGDUR),"") -> 15.75 | D20: =IFERROR(MAX(D_AVGDUR),"") -> 29 | E20: =IFERROR(D20-C20,"") -> 13.25 | F20: =IFERROR(STDEV(D_AVGDUR),"") -> 4.0322362 | G20: =IFERROR(INDEX(D_LABEL,MATCH(D20,D_AVGDUR,0)),"") -> 토 | H20: =IFERROR(INDEX(D_LABEL,MATCH(C20,D_AVGDUR,0)),"") -> 금
A22: ② 취침·기상 시각 규칙성 (11페이지)
A23: 평균 취침시각_분환산 (자정=0, 자정 이전은 음수) | B23: =AVERAGE(D_BEDMIN) -> 17.142857
A24: 취침시각 표준편차 (분) | B24: =STDEV(D_BEDMIN) -> 35.45621
A25: 평균 취침시각 (시각 표시) | B25: =IF(B23<0,1+(B23/1440),B23/1440) -> 0.011904762
A26: 평균 기상시각_분 | B26: =AVERAGE(D_WAKEMIN) -> 397.85714
A27: 기상시각 표준편차 (분) | B27: =STDEV(D_WAKEMIN) -> 18.224787
A28: 평균 기상시각 (시각 표시) | B28: =B26/1440 -> 0.27628968
A29: 목표 침상시간 TIB (분) = 목표수면시간÷목표수면효율 | B29: =NR_TARGET_SLEEP_HR*60/(NR_TARGET_SE/100) -> 494.11765
A30: 목표 취침시각_분 = 평균기상시각분 - 목표TIB | B30: =B26-B29 -> -96.260504
A31: 목표 취침시각 (시각 표시) | B31: =IF(B30<0,1+(B30/1440),B30/1440) -> 0.93315243
A32: 취침시각 규칙성 판정 (참고범위 20분 이내) | B32: =IF(B24<=NR_BEDSD_REF,"참고범위 안","참고범위 초과 (불규칙)") -> 참고범위 초과 (불규칙)
A33: 기상시각 규칙성 판정 (참고범위 20분 이내) | B33: =IF(B27<=NR_WAKESD_REF,"참고범위 안","참고범위 초과 (불규칙)") -> 참고범위 안
A35: ③ 상관계수 · 회귀 (7·8·9·10·14·15페이지)
A36: r (입면잠복기 ↔ 수면효율) | B36: =IFERROR(CORREL(D_SOL,D_SE),"") -> -0.96732026
A37: r (활동시간 ↔ 입면잠복기) | B37: =IFERROR(CORREL(D_ACT,D_SOL),"") -> -0.97318777
A38: r (활동시간 ↔ 수면효율) | B38: =IFERROR(CORREL(D_ACT,D_SE),"") -> 0.95615504
A39: r (심박수 ↔ 호흡수) | B39: =IFERROR(CORREL(D_HR,D_RR),"") -> 0.98853361
A40: r (심박수 ↔ SpO2) | B40: =IFERROR(CORREL(D_HR,D_SPO2),"") -> -0.98853361
A41: r (호흡수 ↔ SpO2) | B41: =IFERROR(CORREL(D_RR,D_SPO2),"") -> -1
A42: r (활동시간 ↔ 소모칼로리 기기값) | B42: =IFERROR(CORREL(D_ACT,D_KCAL_DEVICE),"") -> 0.99797337
A43: r (전날 수면효율 ↔ 당일 활력점수, lag) | B43: =IFERROR(IFERROR(CORREL(S4_Calc_Daily!$H$5:$H$10,S4_Calc_Daily!$U$6:$U$11),""),"") -> -0.13185183
...

Sheet S6_Text_Gen
A1: S6. 페이지별 문구 자동 생성 (초안)
A2: IF 조건 기반으로 조건에 맞는 문장을 조합합니다. 리포트에 넣기 전 자연스럽게 다듬어 사용하세요.
A4: 페이지 | B4: 제목 | C4: 무엇을 의미하나요? (초안) | D4: 제안 (초안)
A5: 03 | B5: 총수면시간 & 수면단계 | C5: ="이번 주 평균 총수면시간은 "&TEXT(NR_TST_AVG,"0")&"분("&TEXT(INT(NR_TST_AVG/60),"0")&"시간 "&TEXT(MOD(NR_TST_AVG,60),"0")&"분)으로, 목표(하루 "&TEXT(NR_TST_TARGET/60,"0")&"시간) 대비 "&IF(NR_TST_AVG>=NR_TST_TARGET,"충족했습니다.","부족했습니다.")&" 총수면시간이 가장 길었던 "&NR_TST_MAXDAY&"요일은 깊은수면 "&TEXT(NR_TST_MAXDAY_DEEP,"0.0")&"%·렘수면 "&TEXT(NR_TST_MAXDAY_REM,"0.0")&"%로 이번 주 중 비중이 가장 높았고, 가장 짧았던 "&NR_TST_MINDAY&"요일은 얕은수면 비중이 "&TEXT(NR_TST_MINDAY_LIGHT,"0.0")&"%로 가장 높았습니다 — 오래 잘수록 깊은수면·렘수면 비중이 늘고 얕은수면 비중은 줄어드는 흐름이 있었습니다." -> 이번 주 평균 총수면시간은 301분(5시간 1분)으로, 목표(하루 7시간) 대비 부족했습니다. 총수면시간이 가장 길었던 토요일은 깊은수면 22.0%·렘수면 30.0%로 이번 주 중 비중이 가장 높았고, 가장 짧았던 금요일은 얕은수면 비중이 65.9%로 가장 높았습니다 — 오래 잘수록 깊은수면·렘수면 비중이 늘고 얕은수면 비중은 줄어드는 흐름이 있었습니다. | D5: ="목표 수면시간(하루 "&TEXT(NR_TST_TARGET/60,"0")&"시간, 주 "&TEXT(NR_TST_TARGET*7/60,"0")&"시간) 대비 이번 주 실제 총수면시간은 약 "&TEXT(NR_TST_AVG*7/60,"0")&"시간으로, 약 "&TEXT(MAX(NR_TST_TARGET*7-NR_TST_AVG*7,0)/60,"0.0")&"시간의 수면부채가 "&IF(NR_TST_AVG<NR_TST_TARGET,"누적되었습니다.","발생하지 않았습니다.")&" 한 번에 몰아 자기보다 하루 20~30분씩 취침시각을 점진적으로 앞당겨 부족분을 줄여가는 것을 목표로 삼을 수 있습니다." -> 목표 수면시간(하루 7시간, 주 49시간) 대비 이번 주 실제 총수면시간은 약 35시간으로, 약 13.9시간의 수면부채가 누적되었습니다. 한 번에 몰아 자기보다 하루 20~30분씩 취침시각을 점진적으로 앞당겨 부족분을 줄여가는 것을 목표로 삼을 수 있습니다.
A6: 04 | B6: 수면효율 | C6: ="이번 주 평균 수면효율은 "&TEXT(NR_SE_AVG,"0")&"%로 참고범위("&TEXT(NR_SE_REF,"0")&"% 이상) "&IF(NR_SE_AVG>=NR_SE_REF,"를 충족했습니다.","에 못 미쳤습니다.")&" 요일별 최저치는 "&TEXT(NR_SE_MIN,"0")&"%("&NR_SE_MINDAY&"요일)까지 내려간 날이 있었습니다. 입면잠복기·각성횟수와 같은 계산식 안에서 함께 움직이는 이유는 7페이지를 확인하세요."&IF(NR_SE_DEVICE_DAYS>0," 이 수치는 웨어러블이 날짜별로 제공한 수면효율이 있으면 그 값을 그대로 반영하고, 제공되지 않은 날만 취침·기상시각 기준 계산값(총수면시간÷침상시간×100)으로 대신합니다.","") -> 이번 주 평균 수면효율은 76%로 참고범위(85% 이상) 에 못 미쳤습니다. 요일별 최저치는 65%(목요일)까지 내려간 날이 있었습니다. 입면잠복기·각성횟수와 같은 계산식 안에서 함께 움직이는 이유는 7페이지를 확인하세요. 이 수치는 웨어러블이 날짜별로 제공한 수면효율이 있으면 그 값을 그대로 반영하고, 제공되지 않은 날만 취침·기상시각 기준 계산값(총수면시간÷침상시간×100)으로 대신합니다. | D6: ="수면효율이 낮은 날이 이어질 때 일반적으로 권장되는 자극조절법입니다 — 잠자리에 누운 지 20분이 지나도 잠들지 않으면 잠시 일어나 있다가 졸릴 때 다시 눕고, 침대는 수면 외 용도로 사용하지 않습니다. 목표: "&TEXT(NR_SE_REF,"0")&"% 이상." -> 수면효율이 낮은 날이 이어질 때 일반적으로 권장되는 자극조절법입니다 — 잠자리에 누운 지 20분이 지나도 잠들지 않으면 잠시 일어나 있다가 졸릴 때 다시 눕고, 침대는 수면 외 용도로 사용하지 않습니다. 목표: 85% 이상.
